Workbook

Sheet Monitor global
B1: Agro
B2: Delta neto* | C2: =+F5 -> -27289.275
B3: Delta neto Potencial* | C3: =MIN(C5:I5) -> -44435.355
B4: *Suma de posiciones netas vendidas de cada producto (SV-SC)+(MV-MC)+(TV-TC) | K4: Tablero de CONTROL
B5: Delta total | D5: =+D9 -> -27289.275 | E5: =+E9 -> -27289.275 | F5: =+F9 -> -27289.275 | G5: =+G9 -> -44435.355 | H5: =+H9 -> -44435.355 | I5: =+I9 -> -44435.355
B7: Delta Futuros | C7: =SUMIFS(Tabla3[[#All],[delta teorico ]],Tabla3[[#All],[Opcion??]],"no") -> -27289.275 | D7: =C7 -> -27289.275 | E7: =D7 -> -27289.275 | F7: =E7 -> -27289.275 | G7: =F7 -> -27289.275 | H7: =G7 -> -27289.275 | I7: =H7 -> -27289.275 | K7: VISUAL BOLSA | L7: =IF((TODAY())-M7>3,"Actualizar","") | M7: =INDEX(INDIRECT("'Saldo CC'!H:H"),1) -> 9/12/2025
B8: Delta Opciones | C8: =SUMIFS(Tabla3[[#All],[-30%22]],Tabla3[[#All],[Opcion??]],"si") -> 0 | D8: =SUMIFS(Tabla3[[#All],[-20%33]],Tabla3[[#All],[Opcion??]],"si") -> 0 | E8: =SUMIFS(Tabla3[[#All],[-10%44]],Tabla3[[#All],[Opcion??]],"si") -> 0 | F8: =SUMIFS(Tabla3[[#All],[0%55]],Tabla3[[#All],[Opcion??]],"si") -> 0 | G8: =SUMIFS(Tabla3[[#All],[10%66]],Tabla3[[#All],[Opcion??]],"si") -> -17146.08 | H8: =SUMIFS(Tabla3[[#All],[20%77]],Tabla3[[#All],[Opcion??]],"si") -> -17146.08 | I8: =SUMIFS(Tabla3[[#All],[30%88]],Tabla3[[#All],[Opcion??]],"si") -> -17146.08 | K8: Colocaciones | L8: =IF((TODAY())-M8>3,"Actualizar","") | M8: =DATE( LEFT(MID(N8,SEARCH("_",N8,SEARCH("_",N8)+1)+1,8),4), MID(MID(N8,SEARCH("_",N8,SEARCH("_",N8)+1)+1,8),5,2), RIGHT(MID(N8,SEARCH("_",N8,SEARCH("_",N8)+1)+1,8),2) ) -> 45999 | N8: ='Colocaciones base'!A27 -> csvnpos_npos_20251208.csv
B9: Delta Tot | C9: =+C7+C8 -> -27289.275 | D9: =+D7+D8 -> -27289.275 | E9: =+E7+E8 -> -27289.275 | F9: =+F7+F8 -> -27289.275 | G9: =+G7+G8 -> -44435.355 | H9: =+H7+H8 -> -44435.355 | I9: =IFERROR(+I7+I8,1) -> -44435.355 | K9: Estirar fórmulas de cartera clientes | M9: =IF(OR(I9=1,I13=1),"SI","NO") -> NO
B10: Var precios MatRfx | C10: -0.3 | D10: -0.2 | E10: -0.1 | F10: 0 | G10: 0.1 | H10: 0.2 | I10: 0.3 | K10: VER CLIENTES CARTERA | M10: =IF(COUNTIF(Tabla3[Columna1],"VER")>=1,"SI","NO") -> NO
B11: Diferencias a integrar Opciones | C11: =(SUMIFS('Cartera clientes'!BW:BW,'Cartera clientes'!$BF:$BF,"si")-SUMIFS('Cartera clientes'!$BZ:$BZ,'Cartera clientes'!$BF:$BF,"si"))/2 -> 0 | D11: =(SUMIFS('Cartera clientes'!BX:BX,'Cartera clientes'!$BF:$BF,"si")-SUMIFS('Cartera clientes'!$BZ:$BZ,'Cartera clientes'!$BF:$BF,"si"))/2 -> 0 | E11: =(SUMIFS('Cartera clientes'!BY:BY,'Cartera clientes'!$BF:$BF,"si")-SUMIFS('Cartera clientes'!$BZ:$BZ,'Cartera clientes'!$BF:$BF,"si"))/2 -> 0 | F11: =(SUMIFS('Cartera clientes'!BZ:BZ,'Cartera clientes'!$BF:$BF,"si")-SUMIFS('Cartera clientes'!$BZ:$BZ,'Cartera clientes'!$BF:$BF,"si"))/2 -> 0 | G11: =(SUMIFS('Cartera clientes'!CA:CA,'Cartera clientes'!$BF:$BF,"si")-SUMIFS('Cartera clientes'!$BZ:$BZ,'Cartera clientes'!$BF:$BF,"si"))/2 -> -96118.509 | H11: =(SUMIFS('Cartera clientes'!CB:CB,'Cartera clientes'!$BF:$BF,"si")-SUMIFS('Cartera clientes'!$BZ:$BZ,'Cartera clientes'!$BF:$BF,"si"))/2 -> -447673.88 | I11: =(SUMIFS('Cartera clientes'!CC:CC,'Cartera clientes'!$BF:$BF,"si")-SUMIFS('Cartera clientes'!$BZ:$BZ,'Cartera clientes'!$BF:$BF,"si"))/2 -> -799229.24 | K11: VER CLIENTES MONITOR | M11: =IF(COUNTIF('Stress test RJO'!AA4:AA13,"VER")>=1,"SI","NO") -> NO
B12: Diferencias a integrar Futuros | C12: =SUMIFS('Cartera clientes'!BP:BP,'Cartera clientes'!$BE:$BE,"futuro")/2 -> 2614631.1 | D12: =SUMIFS('Cartera clientes'!BQ:BQ,'Cartera clientes'!$BE:$BE,"futuro")/2 -> 1743087.4 | E12: =SUMIFS('Cartera clientes'!BR:BR,'Cartera clientes'!$BE:$BE,"futuro")/2 -> 871543.7 | F12: =SUMIFS('Cartera clientes'!BS:BS,'Cartera clientes'!$BE:$BE,"futuro")/2 -> 0 | G12: =SUMIFS('Cartera clientes'!BT:BT,'Cartera clientes'!$BE:$BE,"futuro")/2 -> -871543.7 | H12: =SUMIFS('Cartera clientes'!BU:BU,'Cartera clientes'!$BE:$BE,"futuro")/2 -> -1743087.4 | I12: =SUMIFS('Cartera clientes'!BV:BV,'Cartera clientes'!$BE:$BE,"futuro")/2 -> -2614631.1 | K12: Actualizar tablas dinamicas | M12: =IF(H14+H15=H13,"NO","SI") -> NO
B13: Usd a integrar | C13: =+C11+C12 -> 2614631.1 | D13: =+D11+D12 -> 1743087.4 | E13: =+E11+E12 -> 871543.7 | F13: =+F11+F12 -> 0 | G13: =+G11+G12 -> -967662.21 | H13: =+H11+H12 -> -2190761.3 | I13: =IFERROR(+I11+I12,1) -> -3413860.4 | K13: Statement | L13: =IF((TODAY())-M13>3,"Actualizar","") | M13: =DATE( LEFT(MID(N13,SEARCH("_",N13,SEARCH("_",N13)+1)+1,8),4), MID(MID(N13,SEARCH("_",N13,SEARCH("_",N13)+1)+1,8),5,2), RIGHT(MID(N13,SEARCH("_",N13,SEARCH("_",N13)+1)+1,8),2) ) -> 45999 | N13: ='Statement base'!AP2 -> csvnmny_nmny_20251208.csv
B14: Usd salida Agro | C14: =IF(C11<0,MIN(Tabla!I22:J22)+C11,MIN(Tabla!I22:J22)) -> 0 | D14: =IF(D11<0,MIN(Tabla!K22:L22)+D11,MIN(Tabla!K22:L22)) -> 0 | E14: =IF(E11<0,MIN(Tabla!M22:N22)+E11,MIN(Tabla!M22:N22)) -> 0 | F14: 0 | G14: =IF(G11<0,MIN(Tabla!O22:P22)+G11,MIN(Tabla!O22:P22)) -> -967662.21 | H14: =IF(H11<0,MIN(Tabla!Q22:R22)+H11,MIN(Tabla!Q22:R22)) -> -2190761.3 | I14: =IF(I11<0,MIN(Tabla!S22:T22)+I11,MIN(Tabla!S22:T22)) -> -3413860.4 | K14: Fact_AUM_FyoCapital | L14: =IF((TODAY())-M14>3,"Actualizar","") -> Actualizar | M14: =Fact_AUM_FyoCapital!H2 -> 45996
B15: Usd entrada Agro | C15: =IF(C11>0,MAX(Tabla!I22:J22)+C11,MAX(Tabla!I22:J22)) -> 2614631.1 | D15: =IF(D11>0,MAX(Tabla!K22:L22)+D11,MAX(Tabla!K22:L22)) -> 1743087.4 | E15: =IF(E11>0,MAX(Tabla!M22:N22)+E11,MAX(Tabla!M22:N22)) -> 871543.7 | F15: 0 | G15: =IF(G11>0,MAX(Tabla!O22:P22)+G11,MAX(Tabla!O22:P22)) -> 0 | H15: =IF(H11>0,MAX(Tabla!Q22:R22)+H11,MAX(Tabla!Q22:R22)) -> 0 | I15: =IF(I11>0,MAX(Tabla!S22:T22)+I11,MAX(Tabla!S22:T22)) -> 0 | K15: Ver Productos Colocaciones | M15: =IF(COUNTIF(Colocaciones[[#All],[Producto]],"VER")>=1,"SI","NO") -> NO
B16: Usd por tn a integrar | C16: =(C12+C11)/C9*-1 -> 95.811674 | D16: =(D12+D11)/D9*-1 -> 63.874449 | E16: =(E12+E11)/E9*-1 -> 31.937225 | F16: =(F12+F11)/F9*-1 -> 0 | G16: =(G12+G11)/G9*-1 -> -21.776853 | H16: =(H12+H11)/H9*-1 -> -49.302212 | I16: =(I12+I11)/I9*-1 -> -76.82757 | K16: Hay posicion con Harina de soja? | M16: =IF(COUNTIF(Colocaciones[[#All],[Producto]],"Harina de soja")>=1,"SI","NO") -> NO
B17: Usd a integrar sin FASA | C17: =C18+C19+C11 -> 0 | D17: =D18+D19+D11 -> 0 | E17: =E18+E19+E11 -> 0 | F17: =F18+F19+F11 -> 0 | G17: =G18+G19+G11 -> -192237.02 | H17: =H18+H19+H11 -> -895347.75 | I17: =I18+I19+I11 -> -1598458.5 | K17: Ver Precios | M17: =IF(MAX(Tabla3[[#All],[Precio]])>1000,"SI","NO") -> NO
B18: Usd salida Agro sin FASA | C18: =IF(C11<0,MIN(Tabla!I23:J23)+C11,MIN(Tabla!I23:J23)) -> 0 | D18: =IF(D11<0,MIN(Tabla!K23:L23)+D11,MIN(Tabla!K23:L23)) -> 0 | E18: =IF(E11<0,MIN(Tabla!M23:N23)+E11,MIN(Tabla!M23:N23)) -> 0 | F18: 0 | G18: =IF(G11<0,MIN(Tabla!O23:P25)+G11,MIN(Tabla!O23:P25)) -> -96118.509 | H18: =IF(H11<0,MIN(Tabla!Q23:R25)+H11,MIN(Tabla!Q23:R25)) -> -447673.88 | I18: =IF(I11<0,MIN(Tabla!S23:T25)+I11,MIN(Tabla!S23:T25)) -> -799229.24
B19: Usd entrada Agro sin FASA | C19: =IF(C11>0,MAX(Tabla!I23:J23)+C11,MAX(Tabla!I23:J23)) -> 0 | D19: =IF(D11>0,MAX(Tabla!K23:L23)+D11,MAX(Tabla!K23:L23)) -> 0 | E19: =IF(E11>0,MAX(Tabla!M23:N23)+E11,MAX(Tabla!M23:N23)) -> 0 | F19: 0 | G19: =IF(G11>0,MAX(Tabla!O23:P25)+G11,MAX(Tabla!O23:P25)) -> 0 | H19: =IF(H11>0,MAX(Tabla!Q23:R25)+H11,MAX(Tabla!Q23:R25)) -> 0 | I19: =IF(I11>0,MAX(Tabla!S23:T25)+I11,MAX(Tabla!S23:T25)) -> 0
B20: Usd a integrar FASA | C20: =C13-C17 -> 2614631.1 | D20: =D13-D17 -> 1743087.4 | E20: =E13-E17 -> 871543.7 | F20: =F13-F17 -> 0 | G20: =G13-G17 -> -775425.2 | H20: =H13-H17 -> -1295413.5 | I20: =I13-I17 -> -1815401.9
B21: Usd salida Agro FASA | C21: =C14-C18-C11 -> 0 | D21: =D14-D18-D11 -> 0 | E21: =E14-E18-E11 -> 0 | F21: =F14-F18-F11 -> 0 | G21: =G14-G18-G11 -> -775425.2 | H21: =H14-H18-H11 -> -1295413.5 | I21: =I14-I18-I11 -> -1815401.9
B22: Usd entrada Agro FASA | C22: =C15-C19 -> 2614631.1 | D22: =D15-D19 -> 1743087.4 | E22: =E15-E19 -> 871543.7 | F22: =F15-F19 -> 0 | G22: =G15-G19 -> 0 | H22: =H15-H19 -> 0 | I22: =I15-I19 -> 0

Sheet Cartera clientes
AZ1: Estirar tabla | BD1: llevarlo siempre + Y - | BI1: PRECIOS | BP1: Dif FUTUROS | BW1: DIFERENCIAS Opciones | CD1: Delta opciones
A2: {=Colocaciones[[#All],[Record Code]]} -> Record Code | B2: {=Colocaciones[[#All],[Firm Code]]} -> Firm Code | C2: {=Colocaciones[[#All],[Office Code]]} -> Office Code | D2: {=Colocaciones[[#All],[Sales Code]]} -> Sales Code | E2: {=Colocaciones[[#All],[Account Number]]} -> Account Number | F2: {=Colocaciones[[#All],[Account Class Code]]} -> Account Class Code | G2: {=Colocaciones[[#All],[Account Subclass Code]]} -> Account Subclass Code | H2: {=Colocaciones[[#All],[Account Type Code]]} -> Account Type Code | I2: {=Colocaciones[[#All],[Cusip Code]]} -> Cusip Code | J2: {=Colocaciones[[#All],[Card Number]]} -> Card Number | K2: {=Colocaciones[[#All],[Buy Sell Code]]} -> Buy Sell Code | L2: {=Colocaciones[[#All],[Quantity]]} -> Quantity | M2: {=Colocaciones[[#All],[Security Desc Line 1]]} -> Security Desc Line 1 | N2: {=Colocaciones[[#All],[Formatted Trade Price]]} -> Formatted Trade Price | O2: {=Colocaciones[[#All],[Trade Date]]} -> Trade Date | P2: {=Colocaciones[[#All],[Open Close Code]]} -> Open Close Code | Q2: {=Colocaciones[[#All],[Contract Month]]} -> Contract Month | R2: {=Colocaciones[[#All],[Contract Day]]} -> Contract Day | S2: {=Colocaciones[[#All],[Security Type Code]]} -> Security Type Code | T2: {=Colocaciones[[#All],[Security Subtype Code]]} -> Security Subtype Code | U2: {=Colocaciones[[#All],[Option Strike Price]]} -> Option Strike Price | V2: {=Colocaciones[[#All],[Option Expire Date]]} -> Option Expire Date | W2: {=Colocaciones[[#All],[Spread Code]]} -> Spread Code | X2: {=Colocaciones[[#All],[Account Name]]} -> Account Name | Y2: {=Colocaciones[[#All],[Source Account Number]]} -> Source Account Number | Z2: {=Colocaciones[[#All],[Settlement Date]]} -> Settlement Date | AA2: {=Colocaciones[[#All],[Exchange Code]]} -> Exchange Code | AB2: {=Colocaciones[[#All],[Trade Exchange Code]]} -> Trade Exchange Code | AC2: {=Colocaciones[[#All],[Contract Code]]} -> Contract Code | AD2: {=Colocaciones[[#All],[Contract Symbol]]} -> Contract Symbol | AE2: {=Colocaciones[[#All],[Product Type Code]]} -> Product Type Code | AF2: {=Colocaciones[[#All],[Trade Price]]} -> Trade Price | AG2: {=Colocaciones[[#All],[Trade Calc Control Code]]} -> Trade Calc Control Code | AH2: {=Colocaciones[[#All],[Comment Code 1]]} -> Comment Code 1 | AI2: {=Colocaciones[[#All],[Comment Code 2]]} -> Comment Code 2 | AJ2: {=Colocaciones[[#All],[Give Up Code]]} -> Give Up Code | AK2: {=Colocaciones[[#All],[Give Up Firm Code]]} -> Give Up Firm Code | AL2: {=Colocaciones[[#All],[Buy Side Quantity]]} -> Buy Side Quantity | AM2: {=Colocaciones[[#All],[Sell Side Quantity]]} -> Sell Side Quantity | AN2: {=Colocaciones[[#All],[Account Type Currency Symbol]]} -> Account Type Currency Symbol | AO2: {=Colocaciones[[#All],[Market Value]]} -> Market Value | AP2: {=Colocaciones[[#All],[Close Price]]} -> Close Price | AQ2: {=Colocaciones[[#All],[Underlying Close Price]]} -> Underlying Close Price | AR2: {=IFERROR(Colocaciones[[#All],[Multiplication Factor]]/1000,"Multiplication Factor")} -> Multiplication Factor | AS2: {=Colocaciones[[#All],[Tracer Number]]} -> Tracer Number | AT2: {=Colocaciones[[#All],[Order Number]]} -> Order Number | AU2: {=Colocaciones[[#All],[Delta Factor]]} -> Delta Factor | AV2: {=Colocaciones[[#All],[Bloomberg Root]]} -> Bloomberg Root | AW2: {=Colocaciones[[#All],[Bloomberg Exch Code]]} -> Bloomberg Exch Code | AX2: {=Colocaciones[[#All],[Bloomberg Market Sector]]} -> Bloomberg Market Sector | AY2: {=Colocaciones[[#All],[Producto]]} -> Producto | AZ2: Coversor precio | BA2: Conversor tns | BB2: Precio | BC2: Strike | BD2: Tns | BE2: Tipo | BF2: Opcion?? | BG2: Lado | BH2: Cat opcion | BI2: -30% | BJ2: -20% | BK2: -10% | BL2: 0% | BM2: 10% | BN2: 20% | BO2: 30% | BP2: DF -30% | BQ2: DF -20% | BR2: DF -10% | BS2: DF 0% | BT2: DF 10% | BU2: DF 20% | BV2: DF 30% | BW2: -30%2 | BX2: -20%3 | BY2: -10%4 | BZ2: 0%5 | CA2: 10%6 | CB2: 20%7 | CC2: 30%8 | CD2: -30%22 | CE2: -20%33 | CF2: -10%44 | CG2: 0%55 | CH2: 10%66 | CI2: 20%77 | CJ2: 30%88 | CK2: delta teorico | CL2: Columna1
A3: P | B3: R | C3: 766 | D3: 0 | E3: 13005 | F3: C | G3: O | H3: F1 | I3: .AS-0117026E | J3: 2786 | K3: 1 | L3: 180000 | M3: CALL MAY 26 SOYBEANS 1170 | N3: .15 3/8 | O3: 20250925 | Q3: 202605 | S3: F | T3: C | U3: 1170000000 | V3: 20260424 | X3: FUTUROS Y OPCIONES.C | Z3: 20250925 | AA3: 1 | AB3: 1A | AC3: S- | AF3: .15375000 | AL3: 180000 | AM3: .0000 | AN3: USD | AO3: 1788750 | AP3: 0 | AQ3: 1116750000 | AR3: 50000 | AS3: 5I25 zLB0 | AT3: 115852786 | AU3: 0,3160 | AV3: S | AW3: CBT | AX3: Comdty | AY3: Soja | AZ3: =IF(VLOOKUP(AY3,Conversor!B:C,2,0)="HS",0.01,VLOOKUP(AY3,Conversor!B:C,2,0)) -> 0.36743 | BA3: =IF(BG3="v",-AM3/10000,AL3/10000) -> 18 | BB3: =IF(AQ3=0,AP3/1000000*AZ3,AQ3/1000000*AZ3) -> 410.32745 | BC3: =U3/1000000*AZ3 -> 429.8931 | BD3: =IF(OR(E3="FUTUR",E3="f20176"),0,VLOOKUP(AY3,Conversor!G:I,3,0)*BA3) -> 2449.44 | BE3: =IF(LEFT(M3,4)="call","Call",IF(LEFT(M3,3)="put","Put","Futuro")) -> Call | BF3: =IF(BE3="futuro","no","si") -> si | BG3: =IF(AL3=0,"V","C") -> C | BH3: =IF(BE3="futuro","",CONCATENATE(BG3,LEFT(BE3,1))) -> CC | BI3: =$BB3*(1+BI$2) -> 287.22922 | BJ3: =$BB3*(1+BJ$2) -> 328.26196 | BK3: =$BB3*(1+BK$2) -> 369.29471 | BL3: =$BB3*(1+BL$2) -> 410.32745 | BM3: =$BB3*(1+BM$2) -> 451.3602 | BN3: =$BB3*(1+BN$2) -> 492.39294 | BO3: =$BB3*(1+BO$2) -> 533.42569 | BP3: =IF($BE3="futuro",-($BL3-BI3)*$BD3,0) -> 0 | BQ3: =IF($BE3="futuro",-($BL3-BJ3)*$BD3,0) -> 0 | BR3: =IF($BE3="futuro",-($BL3-BK3)*$BD3,0) -> 0 | BS3: =IF($BE3="futuro",-($BL3-BL3)*$BD3,0) -> 0 | BT3: =IF($BE3="futuro",-($BL3-BM3)*$BD3,0) -> 0 | BU3: =IF($BE3="futuro",-($BL3-BN3)*$BD3,0) -> 0 | BV3: =IF($BE3="futuro",-($BL3-BO3)*$BD3,0) -> 0 | BW3: =IF(AND($BH3="CC",($BC3-BI3)<0),(BI3-$BC3)*$BD3, IF(AND($BH3="VC",($BC3-BI3)<0),($BC3-BI3)*-$BD3, IF(AND($BH3="CP",($BC3-BI3)>0),(BI3-$BC3)*$BD3*-1, IF(AND($BH3="VP",($BC3-BI3)>0),(BI3-$BC3)*$BD3*-1,0)))) -> 0 | BX3: =IF(AND($BH3="CC",($BC3-BJ3)<0),(BJ3-$BC3)*$BD3, IF(AND($BH3="VC",($BC3-BJ3)<0),($BC3-BJ3)*-$BD3, IF(AND($BH3="CP",($BC3-BJ3)>0),(BJ3-$BC3)*$BD3*-1, IF(AND($BH3="VP",($BC3-BJ3)>0),(BJ3-$BC3)*$BD3*-1,0)))) -> 0 | BY3: =IF(AND($BH3="CC",($BC3-BK3)<0),(BK3-$BC3)*$BD3, IF(AND($BH3="VC",($BC3-BK3)<0),($BC3-BK3)*-$BD3, IF(AND($BH3="CP",($BC3-BK3)>0),(BK3-$BC3)*$BD3*-1, IF(AND($BH3="VP",($BC3-BK3)>0),(BK3-$BC3)*$BD3*-1,0)))) -> 0 | BZ3: =IF(AND($BH3="CC",($BC3-BL3)<0),(BL3-$BC3)*$BD3, IF(AND($BH3="VC",($BC3-BL3)<0),($BC3-BL3)*-$BD3, IF(AND($BH3="CP",($BC3-BL3)>0),(BL3-$BC3)*$BD3*-1, IF(AND($BH3="VP",($BC3-BL3)>0),(BL3-$BC3)*$BD3*-1,0)))) -> 0 | CA3: =IF(AND($BH3="CC",($BC3-BM3)<0),(BM3-$BC3)*$BD3, IF(AND($BH3="VC",($BC3-BM3)<0),($BC3-BM3)*-$BD3, IF(AND($BH3="CP",($BC3-BM3)>0),(BM3-$BC3)*$BD3*-1, IF(AND($BH3="VP",($BC3-BM3)>0),(BM3-$BC3)*$BD3*-1,0)))) -> 52582.368 | CB3: =IF(AND($BH3="CC",($BC3-BN3)<0),(BN3-$BC3)*$BD3, IF(AND($BH3="VC",($BC3-BN3)<0),($BC3-BN3)*-$BD3, IF(AND($BH3="CP",($BC3-BN3)>0),(BN3-$BC3)*$BD3*-1, IF(AND($BH3="VP",($BC3-BN3)>0),(BN3-$BC3)*$BD3*-1,0)))) -> 153089.62 | CC3: =IF(AND($BH3="CC",($BC3-BO3)<0),(BO3-$BC3)*$BD3, IF(AND($BH3="VC",($BC3-BO3)<0),($BC3-BO3)*-$BD3, IF(AND($BH3="CP",($BC3-BO3)>0),(BO3-$BC3)*$BD3*-1, IF(AND($BH3="VP",($BC3-BO3)>0),(BO3-$BC3)*$BD3*-1,0)))) -> 253596.86 | CD3: =IF(AND($BH3="CC",($BC3-BI3)<0),$BD3*1, IF(AND($BH3="VC",($BC3-BI3)<0),$BD3*1, IF(AND($BH3="CP",($BC3-BI3)>0),$BD3*-1, IF(AND($BH3="VP",($BC3-BI3)>0),$BD3*-1,0)))) -> 0 | CE3: =IF(AND($BH3="CC",($BC3-BJ3)<0),$BD3*1, IF(AND($BH3="VC",($BC3-BJ3)<0),$BD3*1, IF(AND($BH3="CP",($BC3-BJ3)>0),$BD3*-1, IF(AND($BH3="VP",($BC3-BJ3)>0),$BD3*-1,0)))) -> 0 | CF3: =IF(AND($BH3="CC",($BC3-BK3)<0),$BD3*1, IF(AND($BH3="VC",($BC3-BK3)<0),$BD3*1, IF(AND($BH3="CP",($BC3-BK3)>0),$BD3*-1, IF(AND($BH3="VP",($BC3-BK3)>0),$BD3*-1,0)))) -> 0 | CG3: =IF(AND($BH3="CC",($BC3-BL3)<0),$BD3*1, IF(AND($BH3="VC",($BC3-BL3)<0),$BD3*1, IF(AND($BH3="CP",($BC3-BL3)>0),$BD3*-1, IF(AND($BH3="VP",($BC3-BL3)>0),$BD3*-1,0)))) -> 0 | CH3: =IF(AND($BH3="CC",($BC3-BM3)<0),$BD3*1, IF(AND($BH3="VC",($BC3-BM3)<0),$BD3*1, IF(AND($BH3="CP",($BC3-BM3)>0),$BD3*-1, IF(AND($BH3="VP",($BC3-BM3)>0),$BD3*-1,0)))) -> 2449.44 | CI3: =IF(AND($BH3="CC",($BC3-BN3)<0),$BD3*1, IF(AND($BH3="VC",($BC3-BN3)<0),$BD3*1, IF(AND($BH3="CP",($BC3-BN3)>0),$BD3*-1, IF(AND($BH3="VP",($BC3-BN3)>0),$BD3*-1,0)))) -> 2449.44 | CJ3: =IF(AND($BH3="CC",($BC3-BO3)<0),$BD3*1, IF(AND($BH3="VC",($BC3-BO3)<0),$BD3*1, IF(AND($BH3="CP",($BC3-BO3)>0),$BD3*-1, IF(AND($BH3="VP",($BC3-BO3)>0),$BD3*-1,0)))) -> 2449.44 | CK3: =Tabla3[[#This Row],[Tns]] -> 2449.44 | CL3: =IF(ISERROR(VLOOKUP(VALUE(E3),'Clientes CBOT'!A:A,1,0)),"VER","ok") -> ok
A4: P | B4: R | C4: 766 | D4: 0 | E4: 13006 | F4: C | G4: O | H4: F1 | I4: .AS-0115026C | J4: 9702 | K4: 2 | L4: 100000 | M4: CALL MAR 26 SOYBEANS 1150 | N4: .17 1/8 | O4: 20251205 | Q4: 202603 | S4: F | T4: C | U4: 1150000000 | V4: 20260220 | X4: FUTUROS Y OPCIONES.C | Z4: 20251205 | AA4: 1 | AB4: 1A | AC4: S- | AF4: .17125000 | AL4: 0 | AM4: 10.0000 | AN4: USD | AO4: -637500 | AP4: 0 | AQ4: 1105750000 | AR4: 50000 | AS4: 5L05 G9l0 | AT4: 116429702 | AU4: 0,2870 | AV4: S | AW4: CBT | AX4: Comdty | AY4: Soja | AZ4: =IF(VLOOKUP(AY4,Conversor!B:C,2,0)="HS",0.01,VLOOKUP(AY4,Conversor!B:C,2,0)) -> 0.36743 | BA4: =IF(BG4="v",-AM4/10000,AL4/10000) -> -10 | BB4: =IF(AQ4=0,AP4/1000000*AZ4,AQ4/1000000*AZ4) -> 406.28572 | BC4: =U4/1000000*AZ4 -> 422.5445 | BD4: =IF(OR(E4="FUTUR",E4="f20176"),0,VLOOKUP(AY4,Conversor!G:I,3,0)*BA4) -> -1360.8 | BE4: =IF(LEFT(M4,4)="call","Call",IF(LEFT(M4,3)="put","Put","Futuro")) -> Call | BF4: =IF(BE4="futuro","no","si") -> si | BG4: =IF(AL4=0,"V","C") -> V | BH4: =IF(BE4="futuro","",CONCATENATE(BG4,LEFT(BE4,1))) -> VC | BI4: =$BB4*(1+BI$2) -> 284.40001 | BJ4: =$BB4*(1+BJ$2) -> 325.02858 | BK4: =$BB4*(1+BK$2) -> 365.65715 | BL4: =$BB4*(1+BL$2) -> 406.28572 | BM4: =$BB4*(1+BM$2) -> 446.91429 | BN4: =$BB4*(1+BN$2) -> 487.54287 | BO4: =$BB4*(1+BO$2) -> 528.17144 | BP4: =IF($BE4="futuro",-($BL4-BI4)*$BD4,0) -> 0 | BQ4: =IF($BE4="futuro",-($BL4-BJ4)*$BD4,0) -> 0 | BR4: =IF($BE4="futuro",-($BL4-BK4)*$BD4,0) -> 0 | BS4: =IF($BE4="futuro",-($BL4-BL4)*$BD4,0) -> 0 | BT4: =IF($BE4="futuro",-($BL4-BM4)*$BD4,0) -> 0 | BU4: =IF($BE4="futuro",-($BL4-BN4)*$BD4,0) -> 0 | BV4: =IF($BE4="futuro",-($BL4-BO4)*$BD4,0) -> 0 | BW4: =IF(AND($BH4="CC",($BC4-BI4)<0),(BI4-$BC4)*$BD4, IF(AND($BH4="VC",($BC4-BI4)<0),($BC4-BI4)*-$BD4, IF(AND($BH4="CP",($BC4-BI4)>0),(BI4-$BC4)*$BD4*-1, IF(AND($BH4="VP",($BC4-BI4)>0),(BI4-$BC4)*$BD4*-1,0)))) -> 0 | BX4: =IF(AND($BH4="CC",($BC4-BJ4)<0),(BJ4-$BC4)*$BD4, IF(AND($BH4="VC",($BC4-BJ4)<0),($BC4-BJ4)*-$BD4, IF(AND($BH4="CP",($BC4-BJ4)>0),(BJ4-$BC4)*$BD4*-1, IF(AND($BH4="VP",($BC4-BJ4)>0),(BJ4-$BC4)*$BD4*-1,0)))) -> 0 | BY4: =IF(AND($BH4="CC",($BC4-BK4)<0),(BK4-$BC4)*$BD4, IF(AND($BH4="VC",($BC4-BK4)<0),($BC4-BK4)*-$BD4, IF(AND($BH4="CP",($BC4-BK4)>0),(BK4-$BC4)*$BD4*-1, IF(AND($BH4="VP",($BC4-BK4)>0),(BK4-$BC4)*$BD4*-1,0)))) -> 0 | BZ4: =IF(AND($BH4="CC",($BC4-BL4)<0),(BL4-$BC4)*$BD4, IF(AND($BH4="VC",($BC4-BL4)<0),($BC4-BL4)*-$BD4, IF(AND($BH4="CP",($BC4-BL4)>0),(BL4-$BC4)*$BD4*-1, IF(AND($BH4="VP",($BC4-BL4)>0),(BL4-$BC4)*$BD4*-1,0)))) -> 0 | CA4: =IF(AND($BH4="CC",($BC4-BM4)<0),(BM4-$BC4)*$BD4, IF(AND($BH4="VC",($BC4-BM4)<0),($BC4-BM4)*-$BD4, IF(AND($BH4="CP",($BC4-BM4)>0),(BM4-$BC4)*$BD4*-1, IF(AND($BH4="VP",($BC4-BM4)>0),(BM4-$BC4)*$BD4*-1,0)))) -> -33162.417 | CB4: =IF(AND($BH4="CC",($BC4-BN4)<0),(BN4-$BC4)*$BD4, IF(AND($BH4="VC",($BC4-BN4)<0),($BC4-BN4)*-$BD4, IF(AND($BH4="CP",($BC4-BN4)>0),(BN4-$BC4)*$BD4*-1, IF(AND($BH4="VP",($BC4-BN4)>0),(BN4-$BC4)*$BD4*-1,0)))) -> -88449.778 | CC4: =IF(AND($BH4="CC",($BC4-BO4)<0),(BO4-$BC4)*$BD4, IF(AND($BH4="VC",($BC4-BO4)<0),($BC4-BO4)*-$BD4, IF(AND($BH4="CP",($BC4-BO4)>0),(BO4-$BC4)*$BD4*-1, IF(AND($BH4="VP",($BC4-BO4)>0),(BO4-$BC4)*$BD4*-1,0)))) -> -143737.14 | CD4: =IF(AND($BH4="CC",($BC4-BI4)<0),$BD4*1, IF(AND($BH4="VC",($BC4-BI4)<0),$BD4*1, IF(AND($BH4="CP",($BC4-BI4)>0),$BD4*-1, IF(AND($BH4="VP",($BC4-BI4)>0),$BD4*-1,0)))) -> 0 | CE4: =IF(AND($BH4="CC",($BC4-BJ4)<0),$BD4*1, IF(AND($BH4="VC",($BC4-BJ4)<0),$BD4*1, IF(AND($BH4="CP",($BC4-BJ4)>0),$BD4*-1, IF(AND($BH4="VP",($BC4-BJ4)>0),$BD4*-1,0)))) -> 0 | CF4: =IF(AND($BH4="CC",($BC4-BK4)<0),$BD4*1, IF(AND($BH4="VC",($BC4-BK4)<0),$BD4*1, IF(AND($BH4="CP",($BC4-BK4)>0),$BD4*-1, IF(AND($BH4="VP",($BC4-BK4)>0),$BD4*-1,0)))) -> 0 | CG4: =IF(AND($BH4="CC",($BC4-BL4)<0),$BD4*1, IF(AND($BH4="VC",($BC4-BL4)<0),$BD4*1, IF(AND($BH4="CP",($BC4-BL4)>0),$BD4*-1, IF(AND($BH4="VP",($BC4-BL4)>0),$BD4*-1,0)))) -> 0 | CH4: =IF(AND($BH4="CC",($BC4-BM4)<0),$BD4*1, IF(AND($BH4="VC",($BC4-BM4)<0),$BD4*1, IF(AND($BH4="CP",($BC4-BM4)>0),$BD4*-1, IF(AND($BH4="VP",($BC4-BM4)>0),$BD4*-1,0)))) -> -1360.8 | CI4: =IF(AND($BH4="CC",($BC4-BN4)<0),$BD4*1, IF(AND($BH4="VC",($BC4-BN4)<0),$BD4*1, IF(AND($BH4="CP",($BC4-BN4)>0),$BD4*-1, IF(AND($BH4="VP",($BC4-BN4)>0),$BD4*-1,0)))) -> -1360.8 | CJ4: =IF(AND($BH4="CC",($BC4-BO4)<0),$BD4*1, IF(AND($BH4="VC",($BC4-BO4)<0),$BD4*1, IF(AND($BH4="CP",($BC4-BO4)>0),$BD4*-1, IF(AND($BH4="VP",($BC4-BO4)>0),$BD4*-1,0)))) -> -1360.8 | CK4: =Tabla3[[#This Row],[Tns]] -> -1360.8 | CL4: =IF(ISERROR(VLOOKUP(VALUE(E4),'Clientes CBOT'!A:A,1,0)),"VER","ok") -> ok
A5: P | B5: R | C5: 766 | D5: 0 | E5: 13006 | F5: C | G5: O | H5: F1 | I5: .AS-0118026E | J5: 3793 | K5: 2 | L5: 100000 | M5: CALL MAY 26 SOYBEANS 1180 | N5: .13 3/4 | O5: 20251009 | Q5: 202605 | S5: F | T5: C | U5: 1180000000 | V5: 20260424 | X5: FUTUROS Y OPCIONES.C | Z5: 20251009 | AA5: 1 | AB5: 1A | AC5: S- | AF5: .13750000 | AL5: 0 | AM5: 10.0000 | AN5: USD | AO5: -868750 | AP5: 0 | AQ5: 1116750000 | AR5: 50000 | AS5: 5J09 LRx0 | AT5: 115953793 | AU5: 0,2860 | AV5: S | AW5: CBT | AX5: Comdty | AY5: Soja | AZ5: =IF(VLOOKUP(AY5,Conversor!B:C,2,0)="HS",0.01,VLOOKUP(AY5,Conversor!B:C,2,0)) -> 0.36743 | BA5: =IF(BG5="v",-AM5/10000,AL5/10000) -> -10 | BB5: =IF(AQ5=0,AP5/1000000*AZ5,AQ5/1000000*AZ5) -> 410.32745 | BC5: =U5/1000000*AZ5 -> 433.5674 | BD5: =IF(OR(E5="FUTUR",E5="f20176"),0,VLOOKUP(AY5,Conversor!G:I,3,0)*BA5) -> -1360.8 | BE5: =IF(LEFT(M5,4)="call","Call",IF(LEFT(M5,3)="put","Put","Futuro")) -> Call | BF5: =IF(BE5="futuro","no","si") -> si | BG5: =IF(AL5=0,"V","C") -> V | BH5: =IF(BE5="futuro","",CONCATENATE(BG5,LEFT(BE5,1))) -> VC | BI5: =$BB5*(1+BI$2) -> 287.22922 | BJ5: =$BB5*(1+BJ$2) -> 328.26196 | BK5: =$BB5*(1+BK$2) -> 369.29471 | BL5: =$BB5*(1+BL$2) -> 410.32745 | BM5: =$BB5*(1+BM$2) -> 451.3602 | BN5: =$BB5*(1+BN$2) -> 492.39294 | BO5: =$BB5*(1+BO$2) -> 533.42569 | BP5: =IF($BE5="futuro",-($BL5-BI5)*$BD5,0) -> 0 | BQ5: =IF($BE5="futuro",-($BL5-BJ5)*$BD5,0) -> 0 | BR5: =IF($BE5="futuro",-($BL5-BK5)*$BD5,0) -> 0 | BS5: =IF($BE5="futuro",-($BL5-BL5)*$BD5,0) -> 0 | BT5: =IF($BE5="futuro",-($BL5-BM5)*$BD5,0) -> 0 | BU5: =IF($BE5="futuro",-($BL5-BN5)*$BD5,0) -> 0 | BV5: =IF($BE5="futuro",-($BL5-BO5)*$BD5,0) -> 0 | BW5: =IF(AND($BH5="CC",($BC5-BI5)<0),(BI5-$BC5)*$BD5, IF(AND($BH5="VC",($BC5-BI5)<0),($BC5-BI5)*-$BD5, IF(AND($BH5="CP",($BC5-BI5)>0),(BI5-$BC5)*$BD5*-1, IF(AND($BH5="VP",($BC5-BI5)>0),(BI5-$BC5)*$BD5*-1,0)))) -> 0 | BX5: =IF(AND($BH5="CC",($BC5-BJ5)<0),(BJ5-$BC5)*$BD5, IF(AND($BH5="VC",($BC5-BJ5)<0),($BC5-BJ5)*-$BD5, IF(AND($BH5="CP",($BC5-BJ5)>0),(BJ5-$BC5)*$BD5*-1, IF(AND($BH5="VP",($BC5-BJ5)>0),(BJ5-$BC5)*$BD5*-1,0)))) -> 0 | BY5: =IF(AND($BH5="CC",($BC5-BK5)<0),(BK5-$BC5)*$BD5, IF(AND($BH5="VC",($BC5-BK5)<0),($BC5-BK5)*-$BD5, IF(AND($BH5="CP",($BC5-BK5)>0),(BK5-$BC5)*$BD5*-1, IF(AND($BH5="VP",($BC5-BK5)>0),(BK5-$BC5)*$BD5*-1,0)))) -> 0 | BZ5: =IF(AND($BH5="CC",($BC5-BL5)<0),(BL5-$BC5)*$BD5, IF(AND($BH5="VC",($BC5-BL5)<0),($BC5-BL5)*-$BD5, IF(AND($BH5="CP",($BC5-BL5)>0),(BL5-$BC5)*$BD5*-1, IF(AND($BH5="VP",($BC5-BL5)>0),(BL5-$BC5)*$BD5*-1,0)))) -> 0 | CA5: =IF(AND($BH5="CC",($BC5-BM5)<0),(BM5-$BC5)*$BD5, IF(AND($BH5="VC",($BC5-BM5)<0),($BC5-BM5)*-$BD5, IF(AND($BH5="CP",($BC5-BM5)>0),(BM5-$BC5)*$BD5*-1, IF(AND($BH5="VP",($BC5-BM5)>0),(BM5-$BC5)*$BD5*-1,0)))) -> -24212.439 | CB5: =IF(AND($BH5="CC",($BC5-BN5)<0),(BN5-$BC5)*$BD5, IF(AND($BH5="VC",($BC5-BN5)<0),($BC5-BN5)*-$BD5, IF(AND($BH5="CP",($BC5-BN5)>0),(BN5-$BC5)*$BD5*-1, IF(AND($BH5="VP",($BC5-BN5)>0),(BN5-$BC5)*$BD5*-1,0)))) -> -80049.799 | CC5: =IF(AND($BH5="CC",($BC5-BO5)<0),(BO5-$BC5)*$BD5, IF(AND($BH5="VC",($BC5-BO5)<0),($BC5-BO5)*-$BD5, IF(AND($BH5="CP",($BC5-BO5)>0),(BO5-$BC5)*$BD5*-1, IF(AND($BH5="VP",($BC5-BO5)>0),(BO5-$BC5)*$BD5*-1,0)))) -> -135887.16 | CD5: =IF(AND($BH5="CC",($BC5-BI5)<0),$BD5*1, IF(AND($BH5="VC",($BC5-BI5)<0),$BD5*1, IF(AND($BH5="CP",($BC5-BI5)>0),$BD5*-1, IF(AND($BH5="VP",($BC5-BI5)>0),$BD5*-1,0)))) -> 0 | CE5: =IF(AND($BH5="CC",($BC5-BJ5)<0),$BD5*1, IF(AND($BH5="VC",($BC5-BJ5)<0),$BD5*1, IF(AND($BH5="CP",($BC5-BJ5)>0),$BD5*-1, IF(AND($BH5="VP",($BC5-BJ5)>0),$BD5*-1,0)))) -> 0 | CF5: =IF(AND($BH5="CC",($BC5-BK5)<0),$BD5*1, IF(AND($BH5="VC",($BC5-BK5)<0),$BD5*1, IF(AND($BH5="CP",($BC5-BK5)>0),$BD5*-1, IF(AND($BH5="VP",($BC5-BK5)>0),$BD5*-1,0)))) -> 0 | CG5: =IF(AND($BH5="CC",($BC5-BL5)<0),$BD5*1, IF(AND($BH5="VC",($BC5-BL5)<0),$BD5*1, IF(AND($BH5="CP",($BC5-BL5)>0),$BD5*-1, IF(AND($BH5="VP",($BC5-BL5)>0),$BD5*-1,0)))) -> 0 | CH5: =IF(AND($BH5="CC",($BC5-BM5)<0),$BD5*1, IF(AND($BH5="VC",($BC5-BM5)<0),$BD5*1, IF(AND($BH5="CP",($BC5-BM5)>0),$BD5*-1, IF(AND($BH5="VP",($BC5-BM5)>0),$BD5*-1,0)))) -> -1360.8 | CI5: =IF(AND($BH5="CC",($BC5-BN5)<0),$BD5*1, IF(AND($BH5="VC",($BC5-BN5)<0),$BD5*1, IF(AND($BH5="CP",($BC5-BN5)>0),$BD5*-1, IF(AND($BH5="VP",($BC5-BN5)>0),$BD5*-1,0)))) -> -1360.8 | CJ5: =IF(AND($BH5="CC",($BC5-BO5)<0),$BD5*1, IF(AND($BH5="VC",($BC5-BO5)<0),$BD5*1, IF(AND($BH5="CP",($BC5-BO5)>0),$BD5*-1, IF(AND($BH5="VP",($BC5-BO5)>0),$BD5*-1,0)))) -> -1360.8 | CK5: =Tabla3[[#This Row],[Tns]] -> -1360.8 | CL5: =IF(ISERROR(VLOOKUP(VALUE(E5),'Clientes CBOT'!A:A,1,0)),"VER","ok") -> ok
A6: P | B6: R | C6: 766 | D6: 0 | E6: 13006 | F6: C | G6: O | H6: F1 | I6: .AS-0118026E | J6: 7368 | K6: 2 | L6: 50000 | M6: CALL MAY 26 SOYBEANS 1180 | N6: .16 3/4 | O6: 20251023 | Q6: 202605 | S6: F | T6: C | U6: 1180000000 | V6: 20260424 | X6: FUTUROS Y OPCIONES.C | Z6: 20251023 | AA6: 1 | AB6: 1A | AC6: S- | AF6: .16750000 | AL6: 0 | AM6: 5.0000 | AN6: USD | AO6: -434375 | AP6: 0 | AQ6: 1116750000 | AR6: 50000 | AS6: 5J23 YPc0 | AT6: 116067368 | AU6: 0,2860 | AV6: S | AW6: CBT | AX6: Comdty | AY6: Soja | AZ6: =IF(VLOOKUP(AY6,Conversor!B:C,2,0)="HS",0.01,VLOOKUP(AY6,Conversor!B:C,2,0)) -> 0.36743 | BA6: =IF(BG6="v",-AM6/10000,AL6/10000) -> -5 | BB6: =IF(AQ6=0,AP6/1000000*AZ6,AQ6/1000000*AZ6) -> 410.32745 | BC6: =U6/1000000*AZ6 -> 433.5674 | BD6: =IF(OR(E6="FUTUR",E6="f20176"),0,VLOOKUP(AY6,Conversor!G:I,3,0)*BA6) -> -680.4 | BE6: =IF(LEFT(M6,4)="call","Call",IF(LEFT(M6,3)="put","Put","Futuro")) -> Call | BF6: =IF(BE6="futuro","no","si") -> si | BG6: =IF(AL6=0,"V","C") -> V | BH6: =IF(BE6="futuro","",CONCATENATE(BG6,LEFT(BE6,1))) -> VC | BI6: =$BB6*(1+BI$2) -> 287.22922 | BJ6: =$BB6*(1+BJ$2) -> 328.26196 | BK6: =$BB6*(1+BK$2) -> 369.29471 | BL6: =$BB6*(1+BL$2) -> 410.32745 | BM6: =$BB6*(1+BM$2) -> 451.3602 | BN6: =$BB6*(1+BN$2) -> 492.39294 | BO6: =$BB6*(1+BO$2) -> 533.42569 | BP6: =IF($BE6="futuro",-($BL6-BI6)*$BD6,0) -> 0 | BQ6: =IF($BE6="futuro",-($BL6-BJ6)*$BD6,0) -> 0 | BR6: =IF($BE6="futuro",-($BL6-BK6)*$BD6,0) -> 0 | BS6: =IF($BE6="futuro",-($BL6-BL6)*$BD6,0) -> 0 | BT6: =IF($BE6="futuro",-($BL6-BM6)*$BD6,0) -> 0 | BU6: =IF($BE6="futuro",-($BL6-BN6)*$BD6,0) -> 0 | BV6: =IF($BE6="futuro",-($BL6-BO6)*$BD6,0) -> 0 | BW6: =IF(AND($BH6="CC",($BC6-BI6)<0),(BI6-$BC6)*$BD6, IF(AND($BH6="VC",($BC6-BI6)<0),($BC6-BI6)*-$BD6, IF(AND($BH6="CP",($BC6-BI6)>0),(BI6-$BC6)*$BD6*-1, IF(AND($BH6="VP",($BC6-BI6)>0),(BI6-$BC6)*$BD6*-1,0)))) -> 0 | BX6: =IF(AND($BH6="CC",($BC6-BJ6)<0),(BJ6-$BC6)*$BD6, IF(AND($BH6="VC",($BC6-BJ6)<0),($BC6-BJ6)*-$BD6, IF(AND($BH6="CP",($BC6-BJ6)>0),(BJ6-$BC6)*$BD6*-1, IF(AND($BH6="VP",($BC6-BJ6)>0),(BJ6-$BC6)*$BD6*-1,0)))) -> 0 | BY6: =IF(AND($BH6="CC",($BC6-BK6)<0),(BK6-$BC6)*$BD6, IF(AND($BH6="VC",($BC6-BK6)<0),($BC6-BK6)*-$BD6, IF(AND($BH6="CP",($BC6-BK6)>0),(BK6-$BC6)*$BD6*-1, IF(AND($BH6="VP",($BC6-BK6)>0),(BK6-$BC6)*$BD6*-1,0)))) -> 0 | BZ6: =IF(AND($BH6="CC",($BC6-BL6)<0),(BL6-$BC6)*$BD6, IF(AND($BH6="VC",($BC6-BL6)<0),($BC6-BL6)*-$BD6, IF(AND($BH6="CP",($BC6-BL6)>0),(BL6-$BC6)*$BD6*-1, IF(AND($BH6="VP",($BC6-BL6)>0),(BL6-$BC6)*$BD6*-1,0)))) -> 0 | CA6: =IF(AND($BH6="CC",($BC6-BM6)<0),(BM6-$BC6)*$BD6, IF(AND($BH6="VC",($BC6-BM6)<0),($BC6-BM6)*-$BD6, IF(AND($BH6="CP",($BC6-BM6)>0),(BM6-$BC6)*$BD6*-1, IF(AND($BH6="VP",($BC6-BM6)>0),(BM6-$BC6)*$BD6*-1,0)))) -> -12106.22 | CB6: =IF(AND($BH6="CC",($BC6-BN6)<0),(BN6-$BC6)*$BD6, IF(AND($BH6="VC",($BC6-BN6)<0),($BC6-BN6)*-$BD6, IF(AND($BH6="CP",($BC6-BN6)>0),(BN6-$BC6)*$BD6*-1, IF(AND($BH6="VP",($BC6-BN6)>0),(BN6-$BC6)*$BD6*-1,0)))) -> -40024.899 | CC6: =IF(AND($BH6="CC",($BC6-BO6)<0),(BO6-$BC6)*$BD6, IF(AND($BH6="VC",($BC6-BO6)<0),($BC6-BO6)*-$BD6, IF(AND($BH6="CP",($BC6-BO6)>0),(BO6-$BC6)*$BD6*-1, IF(AND($BH6="VP",($BC6-BO6)>0),(BO6-$BC6)*$BD6*-1,0)))) -> -67943.579 | CD6: =IF(AND($BH6="CC",($BC6-BI6)<0),$BD6*1, IF(AND($BH6="VC",($BC6-BI6)<0),$BD6*1, IF(AND($BH6="CP",($BC6-BI6)>0),$BD6*-1, IF(AND($BH6="VP",($BC6-BI6)>0),$BD6*-1,0)))) -> 0 | CE6: =IF(AND($BH6="CC",($BC6-BJ6)<0),$BD6*1, IF(AND($BH6="VC",($BC6-BJ6)<0),$BD6*1, IF(AND($BH6="CP",($BC6-BJ6)>0),$BD6*-1, IF(AND($BH6="VP",($BC6-BJ6)>0),$BD6*-1,0)))) -> 0 | CF6: =IF(AND($BH6="CC",($BC6-BK6)<0),$BD6*1, IF(AND($BH6="VC",($BC6-BK6)<0),$BD6*1, IF(AND($BH6="CP",($BC6-BK6)>0),$BD6*-1, IF(AND($BH6="VP",($BC6-BK6)>0),$BD6*-1,0)))) -> 0 | CG6: =IF(AND($BH6="CC",($BC6-BL6)<0),$BD6*1, IF(AND($BH6="VC",($BC6-BL6)<0),$BD6*1, IF(AND($BH6="CP",($BC6-BL6)>0),$BD6*-1, IF(AND($BH6="VP",($BC6-BL6)>0),$BD6*-1,0)))) -> 0 | CH6: =IF(AND($BH6="CC",($BC6-BM6)<0),$BD6*1, IF(AND($BH6="VC",($BC6-BM6)<0),$BD6*1, IF(AND($BH6="CP",($BC6-BM6)>0),$BD6*-1, IF(AND($BH6="VP",($BC6-BM6)>0),$BD6*-1,0)))) -> -680.4 | CI6: =IF(AND($BH6="CC",($BC6-BN6)<0),$BD6*1, IF(AND($BH6="VC",($BC6-BN6)<0),$BD6*1, IF(AND($BH6="CP",($BC6-BN6)>0),$BD6*-1, IF(AND($BH6="VP",($BC6-BN6)>0),$BD6*-1,0)))) -> -680.4 | CJ6: =IF(AND($BH6="CC",($BC6-BO6)<0),$BD6*1, IF(AND($BH6="VC",($BC6-BO6)<0),$BD6*1, IF(AND($BH6="CP",($BC6-BO6)>0),$BD6*-1, IF(AND($BH6="VP",($BC6-BO6)>0),$BD6*-1,0)))) -> -680.4 | CK6: =Tabla3[[#This Row],[Tns]] -> -680.4 | CL6: =IF(ISERROR(VLOOKUP(VALUE(E6),'Clientes CBOT'!A:A,1,0)),"VER","ok") -> ok
A7: P | B7: R | C7: 766 | D7: 0 | E7: 13006 | F7: C | G7: O | H7: F1 | I7: .AS-0120026E | J7: 3836 | K7: 2 | L7: 100000 | M7: CALL MAY 26 SOYBEANS 1200 | N7: .11 1/8 | O7: 20251009 | Q7: 202605 | S7: F | T7: C | U7: 1200000000 | V7: 20260424 | X7: FUTUROS Y OPCIONES.C | Z7: 20251009 | AA7: 1 | AB7: 1A | AC7: S- | AF7: .11125000 | AL7: 0 | AM7: 10.0000 | AN7: USD | AO7: -668750 | AP7: 0 | AQ7: 1116750000 | AR7: 50000 | AS7: 5J09 L0h0 | AT7: 115953836 | AU7: 0,2310 | AV7: S | AW7: CBT | AX7: Comdty | AY7: Soja | AZ7: =IF(VLOOKUP(AY7,Conversor!B:C,2,0)="HS",0.01,VLOOKUP(AY7,Conversor!B:C,2,0)) -> 0.36743 | BA7: =IF(BG7="v",-AM7/10000,AL7/10000) -> -10 | BB7: =IF(AQ7=0,AP7/1000000*AZ7,AQ7/1000000*AZ7) -> 410.32745 | BC7: =U7/1000000*AZ7 -> 440.916 | BD7: =IF(OR(E7="FUTUR",E7="f20176"),0,VLOOKUP(AY7,Conversor!G:I,3,0)*BA7) -> -1360.8 | BE7: =IF(LEFT(M7,4)="call","Call",IF(LEFT(M7,3)="put","Put","Futuro")) -> Call | BF7: =IF(BE7="futuro","no","si") -> si | BG7: =IF(AL7=0,"V","C") -> V | BH7: =IF(BE7="futuro","",CONCATENATE(BG7,LEFT(BE7,1))) -> VC | BI7: =$BB7*(1+BI$2) -> 287.22922 | BJ7: =$BB7*(1+BJ$2) -> 328.26196 | BK7: =$BB7*(1+BK$2) -> 369.29471 | BL7: =$BB7*(1+BL$2) -> 410.32745 | BM7: =$BB7*(1+BM$2) -> 451.3602 | BN7: =$BB7*(1+BN$2) -> 492.39294 | BO7: =$BB7*(1+BO$2) -> 533.42569 | BP7: =IF($BE7="futuro",-($BL7-BI7)*$BD7,0) -> 0 | BQ7: =IF($BE7="futuro",-($BL7-BJ7)*$BD7,0) -> 0 | BR7: =IF($BE7="futuro",-($BL7-BK7)*$BD7,0) -> 0 | BS7: =IF($BE7="futuro",-($BL7-BL7)*$BD7,0) -> 0 | BT7: =IF($BE7="futuro",-($BL7-BM7)*$BD7,0) -> 0 | BU7: =IF($BE7="futuro",-($BL7-BN7)*$BD7,0) -> 0 | BV7: =IF($BE7="futuro",-($BL7-BO7)*$BD7,0) -> 0 | BW7: =IF(AND($BH7="CC",($BC7-BI7)<0),(BI7-$BC7)*$BD7, IF(AND($BH7="VC",($BC7-BI7)<0),($BC7-BI7)*-$BD7, IF(AND($BH7="CP",($BC7-BI7)>0),(BI7-$BC7)*$BD7*-1, IF(AND($BH7="VP",($BC7-BI7)>0),(BI7-$BC7)*$BD7*-1,0)))) -> 0 | BX7: =IF(AND($BH7="CC",($BC7-BJ7)<0),(BJ7-$BC7)*$BD7, IF(AND($BH7="VC",($BC7-BJ7)<0),($BC7-BJ7)*-$BD7, IF(AND($BH7="CP",($BC7-BJ7)>0),(BJ7-$BC7)*$BD7*-1, IF(AND($BH7="VP",($BC7-BJ7)>0),(BJ7-$BC7)*$BD7*-1,0)))) -> 0 | BY7: =IF(AND($BH7="CC",($BC7-BK7)<0),(BK7-$BC7)*$BD7, IF(AND($BH7="VC",($BC7-BK7)<0),($BC7-BK7)*-$BD7, IF(AND($BH7="CP",($BC7-BK7)>0),(BK7-$BC7)*$BD7*-1, IF(AND($BH7="VP",($BC7-BK7)>0),(BK7-$BC7)*$BD7*-1,0)))) -> 0 | BZ7: =IF(AND($BH7="CC",($BC7-BL7)<0),(BL7-$BC7)*$BD7, IF(AND($BH7="VC",($BC7-BL7)<0),($BC7-BL7)*-$BD7, IF(AND($BH7="CP",($BC7-BL7)>0),(BL7-$BC7)*$BD7*-1, IF(AND($BH7="VP",($BC7-BL7)>0),(BL7-$BC7)*$BD7*-1,0)))) -> 0 | CA7: =IF(AND($BH7="CC",($BC7-BM7)<0),(BM7-$BC7)*$BD7, IF(AND($BH7="VC",($BC7-BM7)<0),($BC7-BM7)*-$BD7, IF(AND($BH7="CP",($BC7-BM7)>0),(BM7-$BC7)*$BD7*-1, IF(AND($BH7="VP",($BC7-BM7)>0),(BM7-$BC7)*$BD7*-1,0)))) -> -14212.464 | CB7: =IF(AND($BH7="CC",($BC7-BN7)<0),(BN7-$BC7)*$BD7, IF(AND($BH7="VC",($BC7-BN7)<0),($BC7-BN7)*-$BD7, IF(AND($BH7="CP",($BC7-BN7)>0),(BN7-$BC7)*$BD7*-1, IF(AND($BH7="VP",($BC7-BN7)>0),(BN7-$BC7)*$BD7*-1,0)))) -> -70049.824 | CC7: =IF(AND($BH7="CC",($BC7-BO7)<0),(BO7-$BC7)*$BD7, IF(AND($BH7="VC",($BC7-BO7)<0),($BC7-BO7)*-$BD7, IF(AND($BH7="CP",($BC7-BO7)>0),(BO7-$BC7)*$BD7*-1, IF(AND($BH7="VP",($BC7-BO7)>0),(BO7-$BC7)*$BD7*-1,0)))) -> -125887.18 | CD7: =IF(AND($BH7="CC",($BC7-BI7)<0),$BD7*1, IF(AND($BH7="VC",($BC7-BI7)<0),$BD7*1, IF(AND($BH7="CP",($BC7-BI7)>0),$BD7*-1, IF(AND($BH7="VP",($BC7-BI7)>0),$BD7*-1,0)))) -> 0 | CE7: =IF(AND($BH7="CC",($BC7-BJ7)<0),$BD7*1, IF(AND($BH7="VC",($BC7-BJ7)<0),$BD7*1, IF(AND($BH7="CP",($BC7-BJ7)>0),$BD7*-1, IF(AND($BH7="VP",($BC7-BJ7)>0),$BD7*-1,0)))) -> 0 | CF7: =IF(AND($BH7="CC",($BC7-BK7)<0),$BD7*1, IF(AND($BH7="VC",($BC7-BK7)<0),$BD7*1, IF(AND($BH7="CP",($BC7-BK7)>0),$BD7*-1, IF(AND($BH7="VP",($BC7-BK7)>0),$BD7*-1,0)))) -> 0 | CG7: =IF(AND($BH7="CC",($BC7-BL7)<0),$BD7*1, IF(AND($BH7="VC",($BC7-BL7)<0),$BD7*1, IF(AND($BH7="CP",($BC7-BL7)>0),$BD7*-1, IF(AND($BH7="VP",($BC7-BL7)>0),$BD7*-1,0)))) -> 0 | CH7: =IF(AND($BH7="CC",($BC7-BM7)<0),$BD7*1, IF(AND($BH7="VC",($BC7-BM7)<0),$BD7*1, IF(AND($BH7="CP",($BC7-BM7)>0),$BD7*-1, IF(AND($BH7="VP",($BC7-BM7)>0),$BD7*-1,0)))) -> -1360.8 | CI7: =IF(AND($BH7="CC",($BC7-BN7)<0),$BD7*1, IF(AND($BH7="VC",($BC7-BN7)<0),$BD7*1, IF(AND($BH7="CP",($BC7-BN7)>0),$BD7*-1, IF(AND($BH7="VP",($BC7-BN7)>0),$BD7*-1,0)))) -> -1360.8 | CJ7: =IF(AND($BH7="CC",($BC7-BO7)<0),$BD7*1, IF(AND($BH7="VC",($BC7-BO7)<0),$BD7*1, IF(AND($BH7="CP",($BC7-BO7)>0),$BD7*-1, IF(AND($BH7="VP",($BC7-BO7)>0),$BD7*-1,0)))) -> -1360.8 | CK7: =Tabla3[[#This Row],[Tns]] -> -1360.8 | CL7: =IF(ISERROR(VLOOKUP(VALUE(E7),'Clientes CBOT'!A:A,1,0)),"VER","ok") -> ok
A8: P | B8: R | C8: 766 | D8: 0 | E8: 13006 | F8: C | G8: O | H8: F1 | I8: .AS-0120026E | J8: 7394 | K8: 2 | L8: 50000 | M8: CALL MAY 26 SOYBEANS 1200 | N8: .13 3/4 | O8: 20251023 | Q8: 202605 | S8: F | T8: C | U8: 1200000000 | V8: 20260424 | X8: FUTUROS Y OPCIONES.C | Z8: 20251023 | AA8: 1 | AB8: 1A | AC8: S- | AF8: .13750000 | AL8: 0 | AM8: 5.0000 | AN8: USD | AO8: -334375 | AP8: 0 | AQ8: 1116750000 | AR8: 50000 | AS8: 5J23 YVn0 | AT8: 116067394 | AU8: 0,2310 | AV8: S | AW8: CBT | AX8: Comdty | AY8: Soja | AZ8: =IF(VLOOKUP(AY8,Conversor!B:C,2,0)="HS",0.01,VLOOKUP(AY8,Conversor!B:C,2,0)) -> 0.36743 | BA8: =IF(BG8="v",-AM8/10000,AL8/10000) -> -5 | BB8: =IF(AQ8=0,AP8/1000000*AZ8,AQ8/1000000*AZ8) -> 410.32745 | BC8: =U8/1000000*AZ8 -> 440.916 | BD8: =IF(OR(E8="FUTUR",E8="f20176"),0,VLOOKUP(AY8,Conversor!G:I,3,0)*BA8) -> -680.4 | BE8: =IF(LEFT(M8,4)="call","Call",IF(LEFT(M8,3)="put","Put","Futuro")) -> Call | BF8: =IF(BE8="futuro","no","si") -> si | BG8: =IF(AL8=0,"V","C") -> V | BH8: =IF(BE8="futuro","",CONCATENATE(BG8,LEFT(BE8,1))) -> VC | BI8: =$BB8*(1+BI$2) -> 287.22922 | BJ8: =$BB8*(1+BJ$2) -> 328.26196 | BK8: =$BB8*(1+BK$2) -> 369.29471 | BL8: =$BB8*(1+BL$2) -> 410.32745 | BM8: =$BB8*(1+BM$2) -> 451.3602 | BN8: =$BB8*(1+BN$2) -> 492.39294 | BO8: =$BB8*(1+BO$2) -> 533.42569 | BP8: =IF($BE8="futuro",-($BL8-BI8)*$BD8,0) -> 0 | BQ8: =IF($BE8="futuro",-($BL8-BJ8)*$BD8,0) -> 0 | BR8: =IF($BE8="futuro",-($BL8-BK8)*$BD8,0) -> 0 | BS8: =IF($BE8="futuro",-($BL8-BL8)*$BD8,0) -> 0 | BT8: =IF($BE8="futuro",-($BL8-BM8)*$BD8,0) -> 0 | BU8: =IF($BE8="futuro",-($BL8-BN8)*$BD8,0) -> 0 | BV8: =IF($BE8="futuro",-($BL8-BO8)*$BD8,0) -> 0 | BW8: =IF(AND($BH8="CC",($BC8-BI8)<0),(BI8-$BC8)*$BD8, IF(AND($BH8="VC",($BC8-BI8)<0),($BC8-BI8)*-$BD8, IF(AND($BH8="CP",($BC8-BI8)>0),(BI8-$BC8)*$BD8*-1, IF(AND($BH8="VP",($BC8-BI8)>0),(BI8-$BC8)*$BD8*-1,0)))) -> 0 | BX8: =IF(AND($BH8="CC",($BC8-BJ8)<0),(BJ8-$BC8)*$BD8, IF(AND($BH8="VC",($BC8-BJ8)<0),($BC8-BJ8)*-$BD8, IF(AND($BH8="CP",($BC8-BJ8)>0),(BJ8-$BC8)*$BD8*-1, IF(AND($BH8="VP",($BC8-BJ8)>0),(BJ8-$BC8)*$BD8*-1,0)))) -> 0 | BY8: =IF(AND($BH8="CC",($BC8-BK8)<0),(BK8-$BC8)*$BD8, IF(AND($BH8="VC",($BC8-BK8)<0),($BC8-BK8)*-$BD8, IF(AND($BH8="CP",($BC8-BK8)>0),(BK8-$BC8)*$BD8*-1, IF(AND($BH8="VP",($BC8-BK8)>0),(BK8-$BC8)*$BD8*-1,0)))) -> 0 | BZ8: =IF(AND($BH8="CC",($BC8-BL8)<0),(BL8-$BC8)*$BD8, IF(AND($BH8="VC",($BC8-BL8)<0),($BC8-BL8)*-$BD8, IF(AND($BH8="CP",($BC8-BL8)>0),(BL8-$BC8)*$BD8*-1, IF(AND($BH8="VP",($BC8-BL8)>0),(BL8-$BC8)*$BD8*-1,0)))) -> 0 | CA8: =IF(AND($BH8="CC",($BC8-BM8)<0),(BM8-$BC8)*$BD8, IF(AND($BH8="VC",($BC8-BM8)<0),($BC8-BM8)*-$BD8, IF(AND($BH8="CP",($BC8-BM8)>0),(BM8-$BC8)*$BD8*-1, IF(AND($BH8="VP",($BC8-BM8)>0),(BM8-$BC8)*$BD8*-1,0)))) -> -7106.2321 | CB8: =IF(AND($BH8="CC",($BC8-BN8)<0),(BN8-$BC8)*$BD8, IF(AND($BH8="VC",($BC8-BN8)<0),($BC8-BN8)*-$BD8, IF(AND($BH8="CP",($BC8-BN8)>0),(BN8-$BC8)*$BD8*-1, IF(AND($BH8="VP",($BC8-BN8)>0),(BN8-$BC8)*$BD8*-1,0)))) -> -35024.912 | CC8: =IF(AND($BH8="CC",($BC8-BO8)<0),(BO8-$BC8)*$BD8, IF(AND($BH8="VC",($BC8-BO8)<0),($BC8-BO8)*-$BD8, IF(AND($BH8="CP",($BC8-BO8)>0),(BO8-$BC8)*$BD8*-1, IF(AND($BH8="VP",($BC8-BO8)>0),(BO8-$BC8)*$BD8*-1,0)))) -> -62943.592 | CD8: =IF(AND($BH8="CC",($BC8-BI8)<0),$BD8*1, IF(AND($BH8="VC",($BC8-BI8)<0),$BD8*1, IF(AND($BH8="CP",($BC8-BI8)>0),$BD8*-1, IF(AND($BH8="VP",($BC8-BI8)>0),$BD8*-1,0)))) -> 0 | CE8: =IF(AND($BH8="CC",($BC8-BJ8)<0),$BD8*1, IF(AND($BH8="VC",($BC8-BJ8)<0),$BD8*1, IF(AND($BH8="CP",($BC8-BJ8)>0),$BD8*-1, IF(AND($BH8="VP",($BC8-BJ8)>0),$BD8*-1,0)))) -> 0 | CF8: =IF(AND($BH8="CC",($BC8-BK8)<0),$BD8*1, IF(AND($BH8="VC",($BC8-BK8)<0),$BD8*1, IF(AND($BH8="CP",($BC8-BK8)>0),$BD8*-1, IF(AND($BH8="VP",($BC8-BK8)>0),$BD8*-1,0)))) -> 0 | CG8: =IF(AND($BH8="CC",($BC8-BL8)<0),$BD8*1, IF(AND($BH8="VC",($BC8-BL8)<0),$BD8*1, IF(AND($BH8="CP",($BC8-BL8)>0),$BD8*-1, IF(AND($BH8="VP",($BC8-BL8)>0),$BD8*-1,0)))) -> 0 | CH8: =IF(AND($BH8="CC",($BC8-BM8)<0),$BD8*1, IF(AND($BH8="VC",($BC8-BM8)<0),$BD8*1, IF(AND($BH8="CP",($BC8-BM8)>0),$BD8*-1, IF(AND($BH8="VP",($BC8-BM8)>0),$BD8*-1,0)))) -> -680.4 | CI8: =IF(AND($BH8="CC",($BC8-BN8)<0),$BD8*1, IF(AND($BH8="VC",($BC8-BN8)<0),$BD8*1, IF(AND($BH8="CP",($BC8-BN8)>0),$BD8*-1, IF(AND($BH8="VP",($BC8-BN8)>0),$BD8*-1,0)))) -> -680.4 | CJ8: =IF(AND($BH8="CC",($BC8-BO8)<0),$BD8*1, IF(AND($BH8="VC",($BC8-BO8)<0),$BD8*1, IF(AND($BH8="CP",($BC8-BO8)>0),$BD8*-1, IF(AND($BH8="VP",($BC8-BO8)>0),$BD8*-1,0)))) -> -680.4 | CK8: =Tabla3[[#This Row],[Tns]] -> -680.4 | CL8: =IF(ISERROR(VLOOKUP(VALUE(E8),'Clientes CBOT'!A:A,1,0)),"VER","ok") -> ok
A9: P | B9: R | C9: 766 | D9: 0 | E9: 13006 | F9: C | G9: O | H9: F1 | I9: .AS-0122026E | J9: 8416 | K9: 2 | L9: 130000 | M9: CALL MAY 26 SOYBEANS 1220 | N9: .30 1/2 | O9: 20251118 | Q9: 202605 | S9: F | T9: C | U9: 1220000000 | V9: 20260424 | X9: FUTUROS Y OPCIONES.C | Z9: 20251118 | AA9: 1 | AB9: 1A | AC9: S- | AF9: .30500000 | AL9: 0 | AM9: 13.0000 | AN9: USD | AO9: -674375 | AP9: 0 | AQ9: 1116750000 | AR9: 50000 | AS9: 5K18 WeL0 | AT9: 116298416 | AU9: 0,1860 | AV9: S | AW9: CBT | AX9: Comdty | AY9: Soja | AZ9: =IF(VLOOKUP(AY9,Conversor!B:C,2,0)="HS",0.01,VLOOKUP(AY9,Conversor!B:C,2,0)) -> 0.36743 | BA9: =IF(BG9="v",-AM9/10000,AL9/10000) -> -13 | BB9: =IF(AQ9=0,AP9/1000000*AZ9,AQ9/1000000*AZ9) -> 410.32745 | BC9: =U9/1000000*AZ9 -> 448.2646 | BD9: =IF(OR(E9="FUTUR",E9="f20176"),0,VLOOKUP(AY9,Conversor!G:I,3,0)*BA9) -> -1769.04 | BE9: =IF(LEFT(M9,4)="call","Call",IF(LEFT(M9,3)="put","Put","Futuro")) -> Call | BF9: =IF(BE9="futuro","no","si") -> si | BG9: =IF(AL9=0,"V","C") -> V | BH9: =IF(BE9="futuro","",CONCATENATE(BG9,LEFT(BE9,1))) -> VC | BI9: =$BB9*(1+BI$2) -> 287.22922 | BJ9: =$BB9*(1+BJ$2) -> 328.26196 | BK9: =$BB9*(1+BK$2) -> 369.29471 | BL9: =$BB9*(1+BL$2) -> 410.32745 | BM9: =$BB9*(1+BM$2) -> 451.3602 | BN9: =$BB9*(1+BN$2) -> 492.39294 | BO9: =$BB9*(1+BO$2) -> 533.42569 | BP9: =IF($BE9="futuro",-($BL9-BI9)*$BD9,0) -> 0 | BQ9: =IF($BE9="futuro",-($BL9-BJ9)*$BD9,0) -> 0 | BR9: =IF($BE9="futuro",-($BL9-BK9)*$BD9,0) -> 0 | BS9: =IF($BE9="futuro",-($BL9-BL9)*$BD9,0) -> 0 | BT9: =IF($BE9="futuro",-($BL9-BM9)*$BD9,0) -> 0 | BU9: =IF($BE9="futuro",-($BL9-BN9)*$BD9,0) -> 0 | BV9: =IF($BE9="futuro",-($BL9-BO9)*$BD9,0) -> 0 | BW9: =IF(AND($BH9="CC",($BC9-BI9)<0),(BI9-$BC9)*$BD9, IF(AND($BH9="VC",($BC9-BI9)<0),($BC9-BI9)*-$BD9, IF(AND($BH9="CP",($BC9-BI9)>0),(BI9-$BC9)*$BD9*-1, IF(AND($BH9="VP",($BC9-BI9)>0),(BI9-$BC9)*$BD9*-1,0)))) -> 0 | BX9: =IF(AND($BH9="CC",($BC9-BJ9)<0),(BJ9-$BC9)*$BD9, IF(AND($BH9="VC",($BC9-BJ9)<0),($BC9-BJ9)*-$BD9, IF(AND($BH9="CP",($BC9-BJ9)>0),(BJ9-$BC9)*$BD9*-1, IF(AND($BH9="VP",($BC9-BJ9)>0),(BJ9-$BC9)*$BD9*-1,0)))) -> 0 | BY9: =IF(AND($BH9="CC",($BC9-BK9)<0),(BK9-$BC9)*$BD9, IF(AND($BH9="VC",($BC9-BK9)<0),($BC9-BK9)*-$BD9, IF(AND($BH9="CP",($BC9-BK9)>0),(BK9-$BC9)*$BD9*-1, IF(AND($BH9="VP",($BC9-BK9)>0),(BK9-$BC9)*$BD9*-1,0)))) -> 0 | BZ9: =IF(AND($BH9="CC",($BC9-BL9)<0),(BL9-$BC9)*$BD9, IF(AND($BH9="VC",($BC9-BL9)<0),($BC9-BL9)*-$BD9, IF(AND($BH9="CP",($BC9-BL9)>0),(BL9-$BC9)*$BD9*-1, IF(AND($BH9="VP",($BC9-BL9)>0),(BL9-$BC9)*$BD9*-1,0)))) -> 0 | CA9: =IF(AND($BH9="CC",($BC9-BM9)<0),(BM9-$BC9)*$BD9, IF(AND($BH9="VC",($BC9-BM9)<0),($BC9-BM9)*-$BD9, IF(AND($BH9="CP",($BC9-BM9)>0),(BM9-$BC9)*$BD9*-1, IF(AND($BH9="VP",($BC9-BM9)>0),(BM9-$BC9)*$BD9*-1,0)))) -> -5476.2362 | CB9: =IF(AND($BH9="CC",($BC9-BN9)<0),(BN9-$BC9)*$BD9, IF(AND($BH9="VC",($BC9-BN9)<0),($BC9-BN9)*-$BD9, IF(AND($BH9="CP",($BC9-BN9)>0),(BN9-$BC9)*$BD9*-1, IF(AND($BH9="VP",($BC9-BN9)>0),(BN9-$BC9)*$BD9*-1,0)))) -> -78064.804 | CC9: =IF(AND($BH9="CC",($BC9-BO9)<0),(BO9-$BC9)*$BD9, IF(AND($BH9="VC",($BC9-BO9)<0),($BC9-BO9)*-$BD9, IF(AND($BH9="CP",($BC9-BO9)>0),(BO9-$BC9)*$BD9*-1, IF(AND($BH9="VP",($BC9-BO9)>0),(BO9-$BC9)*$BD9*-1,0)))) -> -150653.37 | CD9: =IF(AND($BH9="CC",($BC9-BI9)<0),$BD9*1, IF(AND($BH9="VC",($BC9-BI9)<0),$BD9*1, IF(AND($BH9="CP",($BC9-BI9)>0),$BD9*-1, IF(AND($BH9="VP",($BC9-BI9)>0),$BD9*-1,0)))) -> 0 | CE9: =IF(AND($BH9="CC",($BC9-BJ9)<0),$BD9*1, IF(AND($BH9="VC",($BC9-BJ9)<0),$BD9*1, IF(AND($BH9="CP",($BC9-BJ9)>0),$BD9*-1, IF(AND($BH9="VP",($BC9-BJ9)>0),$BD9*-1,0)))) -> 0 | CF9: =IF(AND($BH9="CC",($BC9-BK9)<0),$BD9*1, IF(AND($BH9="VC",($BC9-BK9)<0),$BD9*1, IF(AND($BH9="CP",($BC9-BK9)>0),$BD9*-1, IF(AND($BH9="VP",($BC9-BK9)>0),$BD9*-1,0)))) -> 0 | CG9: =IF(AND($BH9="CC",($BC9-BL9)<0),$BD9*1, IF(AND($BH9="VC",($BC9-BL9)<0),$BD9*1, IF(AND($BH9="CP",($BC9-BL9)>0),$BD9*-1, IF(AND($BH9="VP",($BC9-BL9)>0),$BD9*-1,0)))) -> 0 | CH9: =IF(AND($BH9="CC",($BC9-BM9)<0),$BD9*1, IF(AND($BH9="VC",($BC9-BM9)<0),$BD9*1, IF(AND($BH9="CP",($BC9-BM9)>0),$BD9*-1, IF(AND($BH9="VP",($BC9-BM9)>0),$BD9*-1,0)))) -> -1769.04 | CI9: =IF(AND($BH9="CC",($BC9-BN9)<0),$BD9*1, IF(AND($BH9="VC",($BC9-BN9)<0),$BD9*1, IF(AND($BH9="CP",($BC9-BN9)>0),$BD9*-1, IF(AND($BH9="VP",($BC9-BN9)>0),$BD9*-1,0)))) -> -1769.04 | CJ9: =IF(AND($BH9="CC",($BC9-BO9)<0),$BD9*1, IF(AND($BH9="VC",($BC9-BO9)<0),$BD9*1, IF(AND($BH9="CP",($BC9-BO9)>0),$BD9*-1, IF(AND($BH9="VP",($BC9-BO9)>0),$BD9*-1,0)))) -> -1769.04 | CK9: =Tabla3[[#This Row],[Tns]] -> -1769.04 | CL9: =IF(ISERROR(VLOOKUP(VALUE(E9),'Clientes CBOT'!A:A,1,0)),"VER","ok") -> ok
A10: P | B10: R | C10: 766 | D10: 0 | E10: 13006 | F10: C | G10: O | H10: F1 | I10: .AS-0122026E | J10: 4956 | K10: 2 | L10: 100000 | M10: CALL MAY 26 SOYBEANS 1220 | N10: .31 | O10: 20251118 | Q10: 202605 | S10: F | T10: C | U10: 1220000000 | V10: 20260424 | X10: FUTUROS Y OPCIONES.C | Z10: 20251118 | AA10: 1 | AB10: 1A | AC10: S- | AF10: .31000000 | AL10: 0 | AM10: 10.0000 | AN10: USD | AO10: -518750 | AP10: 0 | AQ10: 1116750000 | AR10: 50000 | AS10: 5K18 JH90 | AT10: 116294956 | AU10: 0,1860 | AV10: S | AW10: CBT | AX10: Comdty | AY10: Soja | AZ10: =IF(VLOOKUP(AY10,Conversor!B:C,2,0)="HS",0.01,VLOOKUP(AY10,Conversor!B:C,2,0)) -> 0.36743 | BA10: =IF(BG10="v",-AM10/10000,AL10/10000) -> -10 | BB10: =IF(AQ10=0,AP10/1000000*AZ10,AQ10/1000000*AZ10) -> 410.32745 | BC10: =U10/1000000*AZ10 -> 448.2646 | BD10: =IF(OR(E10="FUTUR",E10="f20176"),0,VLOOKUP(AY10,Conversor!G:I,3,0)*BA10) -> -1360.8 | BE10: =IF(LEFT(M10,4)="call","Call",IF(LEFT(M10,3)="put","Put","Futuro")) -> Call | BF10: =IF(BE10="futuro","no","si") -> si | BG10: =IF(AL10=0,"V","C") -> V | BH10: =IF(BE10="futuro","",CONCATENATE(BG10,LEFT(BE10,1))) -> VC | BI10: =$BB10*(1+BI$2) -> 287.22922 | BJ10: =$BB10*(1+BJ$2) -> 328.26196 | BK10: =$BB10*(1+BK$2) -> 369.29471 | BL10: =$BB10*(1+BL$2) -> 410.32745 | BM10: =$BB10*(1+BM$2) -> 451.3602 | BN10: =$BB10*(1+BN$2) -> 492.39294 | BO10: =$BB10*(1+BO$2) -> 533.42569 | BP10: =IF($BE10="futuro",-($BL10-BI10)*$BD10,0) -> 0 | BQ10: =IF($BE10="futuro",-($BL10-BJ10)*$BD10,0) -> 0 | BR10: =IF($BE10="futuro",-($BL10-BK10)*$BD10,0) -> 0 | BS10: =IF($BE10="futuro",-($BL10-BL10)*$BD10,0) -> 0 | BT10: =IF($BE10="futuro",-($BL10-BM10)*$BD10,0) -> 0 | BU10: =IF($BE10="futuro",-($BL10-BN10)*$BD10,0) -> 0 | BV10: =IF($BE10="futuro",-($BL10-BO10)*$BD10,0) -> 0 | BW10: =IF(AND($BH10="CC",($BC10-BI10)<0),(BI10-$BC10)*$BD10, IF(AND($BH10="VC",($BC10-BI10)<0),($BC10-BI10)*-$BD10, IF(AND($BH10="CP",($BC10-BI10)>0),(BI10-$BC10)*$BD10*-1, IF(AND($BH10="VP",($BC10-BI10)>0),(BI10-$BC10)*$BD10*-1,0)))) -> 0 | BX10: =IF(AND($BH10="CC",($BC10-BJ10)<0),(BJ10-$BC10)*$BD10, IF(AND($BH10="VC",($BC10-BJ10)<0),($BC10-BJ10)*-$BD10, IF(AND($BH10="CP",($BC10-BJ10)>0),(BJ10-$BC10)*$BD10*-1, IF(AND($BH10="VP",($BC10-BJ10)>0),(BJ10-$BC10)*$BD10*-1,0)))) -> 0 | BY10: =IF(AND($BH10="CC",($BC10-BK10)<0),(BK10-$BC10)*$BD10, IF(AND($BH10="VC",($BC10-BK10)<0),($BC10-BK10)*-$BD10, IF(AND($BH10="CP",($BC10-BK10)>0),(BK10-$BC10)*$BD10*-1, IF(AND($BH10="VP",($BC10-BK10)>0),(BK10-$BC10)*$BD10*-1,0)))) -> 0 | BZ10: =IF(AND($BH10="CC",($BC10-BL10)<0),(BL10-$BC10)*$BD10, IF(AND($BH10="VC",($BC10-BL10)<0),($BC10-BL10)*-$BD10, IF(AND($BH10="CP",($BC10-BL10)>0),(BL10-$BC10)*$BD10*-1, IF(AND($BH10="VP",($BC10-BL10)>0),(BL10-$BC10)*$BD10*-1,0)))) -> 0 | CA10: =IF(AND($BH10="CC",($BC10-BM10)<0),(BM10-$BC10)*$BD10, IF(AND($BH10="VC",($BC10-BM10)<0),($BC10-BM10)*-$BD10, IF(AND($BH10="CP",($BC10-BM10)>0),(BM10-$BC10)*$BD10*-1, IF(AND($BH10="VP",($BC10-BM10)>0),(BM10-$BC10)*$BD10*-1,0)))) -> -4212.4894 | CB10: =IF(AND($BH10="CC",($BC10-BN10)<0),(BN10-$BC10)*$BD10, IF(AND($BH10="VC",($BC10-BN10)<0),($BC10-BN10)*-$BD10, IF(AND($BH10="CP",($BC10-BN10)>0),(BN10-$BC10)*$BD10*-1, IF(AND($BH10="VP",($BC10-BN10)>0),(BN10-$BC10)*$BD10*-1,0)))) -> -60049.849 | CC10: =IF(AND($BH10="CC",($BC10-BO10)<0),(BO10-$BC10)*$BD10, IF(AND($BH10="VC",($BC10-BO10)<0),($BC10-BO10)*-$BD10, IF(AND($BH10="CP",($BC10-BO10)>0),(BO10-$BC10)*$BD10*-1, IF(AND($BH10="VP",($BC10-BO10)>0),(BO10-$BC10)*$BD10*-1,0)))) -> -115887.21 | CD10: =IF(AND($BH10="CC",($BC10-BI10)<0),$BD10*1, IF(AND($BH10="VC",($BC10-BI10)<0),$BD10*1, IF(AND($BH10="CP",($BC10-BI10)>0),$BD10*-1, IF(AND($BH10="VP",($BC10-BI10)>0),$BD10*-1,0)))) -> 0 | CE10: =IF(AND($BH10="CC",($BC10-BJ10)<0),$BD10*1, IF(AND($BH10="VC",($BC10-BJ10)<0),$BD10*1, IF(AND($BH10="CP",($BC10-BJ10)>0),$BD10*-1, IF(AND($BH10="VP",($BC10-BJ10)>0),$BD10*-1,0)))) -> 0 | CF10: =IF(AND($BH10="CC",($BC10-BK10)<0),$BD10*1, IF(AND($BH10="VC",($BC10-BK10)<0),$BD10*1, IF(AND($BH10="CP",($BC10-BK10)>0),$BD10*-1, IF(AND($BH10="VP",($BC10-BK10)>0),$BD10*-1,0)))) -> 0 | CG10: =IF(AND($BH10="CC",($BC10-BL10)<0),$BD10*1, IF(AND($BH10="VC",($BC10-BL10)<0),$BD10*1, IF(AND($BH10="CP",($BC10-BL10)>0),$BD10*-1, IF(AND($BH10="VP",($BC10-BL10)>0),$BD10*-1,0)))) -> 0 | CH10: =IF(AND($BH10="CC",($BC10-BM10)<0),$BD10*1, IF(AND($BH10="VC",($BC10-BM10)<0),$BD10*1, IF(AND($BH10="CP",($BC10-BM10)>0),$BD10*-1, IF(AND($BH10="VP",($BC10-BM10)>0),$BD10*-1,0)))) -> -1360.8 | CI10: =IF(AND($BH10="CC",($BC10-BN10)<0),$BD10*1, IF(AND($BH10="VC",($BC10-BN10)<0),$BD10*1, IF(AND($BH10="CP",($BC10-BN10)>0),$BD10*-1, IF(AND($BH10="VP",($BC10-BN10)>0),$BD10*-1,0)))) -> -1360.8 | CJ10: =IF(AND($BH10="CC",($BC10-BO10)<0),$BD10*1, IF(AND($BH10="VC",($BC10-BO10)<0),$BD10*1, IF(AND($BH10="CP",($BC10-BO10)>0),$BD10*-1, IF(AND($BH10="VP",($BC10-BO10)>0),$BD10*-1,0)))) -> -1360.8 | CK10: =Tabla3[[#This Row],[Tns]] -> -1360.8 | CL10: =IF(ISERROR(VLOOKUP(VALUE(E10),'Clientes CBOT'!A:A,1,0)),"VER","ok") -> ok
A11: P | B11: R | C11: 766 | D11: 0 | E11: 13007 | F11: C | G11: O | H11: F1 | I11: .AS-0115026C | J11: 9710 | K11: 2 | L11: 100000 | M11: CALL MAR 26 SOYBEANS 1150 | N11: .17 1/8 | O11: 20251205 | Q11: 202603 | S11: F | T11: C | U11: 1150000000 | V11: 20260220 | X11: FUTUROS Y OPCIONES.C | Z11: 20251205 | AA11: 1 | AB11: 1A | AC11: S- | AF11: .17125000 | AL11: 0 | AM11: 10.0000 | AN11: USD | AO11: -637500 | AP11: 0 | AQ11: 1105750000 | AR11: 50000 | AS11: 5L05 G9k0 | AT11: 116429710 | AU11: 0,2870 | AV11: S | AW11: CBT | AX11: Comdty | AY11: Soja | AZ11: =IF(VLOOKUP(AY11,Conversor!B:C,2,0)="HS",0.01,VLOOKUP(AY11,Conversor!B:C,2,0)) -> 0.36743 | BA11: =IF(BG11="v",-AM11/10000,AL11/10000) -> -10 | BB11: =IF(AQ11=0,AP11/1000000*AZ11,AQ11/1000000*AZ11) -> 406.28572 | BC11: =U11/1000000*AZ11 -> 422.5445 | BD11: =IF(OR(E11="FUTUR",E11="f20176"),0,VLOOKUP(AY11,Conversor!G:I,3,0)*BA11) -> -1360.8 | BE11: =IF(LEFT(M11,4)="call","Call",IF(LEFT(M11,3)="put","Put","Futuro")) -> Call | BF11: =IF(BE11="futuro","no","si") -> si | BG11: =IF(AL11=0,"V","C") -> V | BH11: =IF(BE11="futuro","",CONCATENATE(BG11,LEFT(BE11,1))) -> VC | BI11: =$BB11*(1+BI$2) -> 284.40001 | BJ11: =$BB11*(1+BJ$2) -> 325.02858 | BK11: =$BB11*(1+BK$2) -> 365.65715 | BL11: =$BB11*(1+BL$2) -> 406.28572 | BM11: =$BB11*(1+BM$2) -> 446.91429 | BN11: =$BB11*(1+BN$2) -> 487.54287 | BO11: =$BB11*(1+BO$2) -> 528.17144 | BP11: =IF($BE11="futuro",-($BL11-BI11)*$BD11,0) -> 0 | BQ11: =IF($BE11="futuro",-($BL11-BJ11)*$BD11,0) -> 0 | BR11: =IF($BE11="futuro",-($BL11-BK11)*$BD11,0) -> 0 | BS11: =IF($BE11="futuro",-($BL11-BL11)*$BD11,0) -> 0 | BT11: =IF($BE11="futuro",-($BL11-BM11)*$BD11,0) -> 0 | BU11: =IF($BE11="futuro",-($BL11-BN11)*$BD11,0) -> 0 | BV11: =IF($BE11="futuro",-($BL11-BO11)*$BD11,0) -> 0 | BW11: =IF(AND($BH11="CC",($BC11-BI11)<0),(BI11-$BC11)*$BD11, IF(AND($BH11="VC",($BC11-BI11)<0),($BC11-BI11)*-$BD11, IF(AND($BH11="CP",($BC11-BI11)>0),(BI11-$BC11)*$BD11*-1, IF(AND($BH11="VP",($BC11-BI11)>0),(BI11-$BC11)*$BD11*-1,0)))) -> 0 | BX11: =IF(AND($BH11="CC",($BC11-BJ11)<0),(BJ11-$BC11)*$BD11, IF(AND($BH11="VC",($BC11-BJ11)<0),($BC11-BJ11)*-$BD11, IF(AND($BH11="CP",($BC11-BJ11)>0),(BJ11-$BC11)*$BD11*-1, IF(AND($BH11="VP",($BC11-BJ11)>0),(BJ11-$BC11)*$BD11*-1,0)))) -> 0 | BY11: =IF(AND($BH11="CC",($BC11-BK11)<0),(BK11-$BC11)*$BD11, IF(AND($BH11="VC",($BC11-BK11)<0),($BC11-BK11)*-$BD11, IF(AND($BH11="CP",($BC11-BK11)>0),(BK11-$BC11)*$BD11*-1, IF(AND($BH11="VP",($BC11-BK11)>0),(BK11-$BC11)*$BD11*-1,0)))) -> 0 | BZ11: =IF(AND($BH11="CC",($BC11-BL11)<0),(BL11-$BC11)*$BD11, IF(AND($BH11="VC",($BC11-BL11)<0),($BC11-BL11)*-$BD11, IF(AND($BH11="CP",($BC11-BL11)>0),(BL11-$BC11)*$BD11*-1, IF(AND($BH11="VP",($BC11-BL11)>0),(BL11-$BC11)*$BD11*-1,0)))) -> 0 | CA11: =IF(AND($BH11="CC",($BC11-BM11)<0),(BM11-$BC11)*$BD11, IF(AND($BH11="VC",($BC11-BM11)<0),($BC11-BM11)*-$BD11, IF(AND($BH11="CP",($BC11-BM11)>0),(BM11-$BC11)*$BD11*-1, IF(AND($BH11="VP",($BC11-BM11)>0),(BM11-$BC11)*$BD11*-1,0)))) -> -33162.417 | CB11: =IF(AND($BH11="CC",($BC11-BN11)<0),(BN11-$BC11)*$BD11, IF(AND($BH11="VC",($BC11-BN11)<0),($BC11-BN11)*-$BD11, IF(AND($BH11="CP",($BC11-BN11)>0),(BN11-$BC11)*$BD11*-1, IF(AND($BH11="VP",($BC11-BN11)>0),(BN11-$BC11)*$BD11*-1,0)))) -> -88449.778 | CC11: =IF(AND($BH11="CC",($BC11-BO11)<0),(BO11-$BC11)*$BD11, IF(AND($BH11="VC",($BC11-BO11)<0),($BC11-BO11)*-$BD11, IF(AND($BH11="CP",($BC11-BO11)>0),(BO11-$BC11)*$BD11*-1, IF(AND($BH11="VP",($BC11-BO11)>0),(BO11-$BC11)*$BD11*-1,0)))) -> -143737.14 | CD11: =IF(AND($BH11="CC",($BC11-BI11)<0),$BD11*1, IF(AND($BH11="VC",($BC11-BI11)<0),$BD11*1, IF(AND($BH11="CP",($BC11-BI11)>0),$BD11*-1, IF(AND($BH11="VP",($BC11-BI11)>0),$BD11*-1,0)))) -> 0 | CE11: =IF(AND($BH11="CC",($BC11-BJ11)<0),$BD11*1, IF(AND($BH11="VC",($BC11-BJ11)<0),$BD11*1, IF(AND($BH11="CP",($BC11-BJ11)>0),$BD11*-1, IF(AND($BH11="VP",($BC11-BJ11)>0),$BD11*-1,0)))) -> 0 | CF11: =IF(AND($BH11="CC",($BC11-BK11)<0),$BD11*1, IF(AND($BH11="VC",($BC11-BK11)<0),$BD11*1, IF(AND($BH11="CP",($BC11-BK11)>0),$BD11*-1, IF(AND($BH11="VP",($BC11-BK11)>0),$BD11*-1,0)))) -> 0 | CG11: =IF(AND($BH11="CC",($BC11-BL11)<0),$BD11*1, IF(AND($BH11="VC",($BC11-BL11)<0),$BD11*1, IF(AND($BH11="CP",($BC11-BL11)>0),$BD11*-1, IF(AND($BH11="VP",($BC11-BL11)>0),$BD11*-1,0)))) -> 0 | CH11: =IF(AND($BH11="CC",($BC11-BM11)<0),$BD11*1, IF(AND($BH11="VC",($BC11-BM11)<0),$BD11*1, IF(AND($BH11="CP",($BC11-BM11)>0),$BD11*-1, IF(AND($BH11="VP",($BC11-BM11)>0),$BD11*-1,0)))) -> -1360.8 | CI11: =IF(AND($BH11="CC",($BC11-BN11)<0),$BD11*1, IF(AND($BH11="VC",($BC11-BN11)<0),$BD11*1, IF(AND($BH11="CP",($BC11-BN11)>0),$BD11*-1, IF(AND($BH11="VP",($BC11-BN11)>0),$BD11*-1,0)))) -> -1360.8 | CJ11: =IF(AND($BH11="CC",($BC11-BO11)<0),$BD11*1, IF(AND($BH11="VC",($BC11-BO11)<0),$BD11*1, IF(AND($BH11="CP",($BC11-BO11)>0),$BD11*-1, IF(AND($BH11="VP",($BC11-BO11)>0),$BD11*-1,0)))) -> -1360.8 | CK11: =Tabla3[[#This Row],[Tns]] -> -1360.8 | CL11: =IF(ISERROR(VLOOKUP(VALUE(E11),'Clientes CBOT'!A:A,1,0)),"VER","ok") -> ok
A12: P | B12: R | C12: 766 | D12: 0 | E12: 13007 | F12: C | G12: O | H12: F1 | I12: .AS-0118026E | J12: 3802 | K12: 2 | L12: 100000 | M12: CALL MAY 26 SOYBEANS 1180 | N12: .13 1/2 | O12: 20251009 | Q12: 202605 | S12: F | T12: C | U12: 1180000000 | V12: 20260424 | X12: FUTUROS Y OPCIONES.C | Z12: 20251009 | AA12: 1 | AB12: 1A | AC12: S- | AF12: .13500000 | AL12: 0 | AM12: 10.0000 | AN12: USD | AO12: -868750 | AP12: 0 | AQ12: 1116750000 | AR12: 50000 | AS12: 5J09 MKX0 | AT12: 115953802 | AU12: 0,2860 | AV12: S | AW12: CBT | AX12: Comdty | AY12: Soja | AZ12: =IF(VLOOKUP(AY12,Conversor!B:C,2,0)="HS",0.01,VLOOKUP(AY12,Conversor!B:C,2,0)) -> 0.36743 | BA12: =IF(BG12="v",-AM12/10000,AL12/10000) -> -10 | BB12: =IF(AQ12=0,AP12/1000000*AZ12,AQ12/1000000*AZ12) -> 410.32745 | BC12: =U12/1000000*AZ12 -> 433.5674 | BD12: =IF(OR(E12="FUTUR",E12="f20176"),0,VLOOKUP(AY12,Conversor!G:I,3,0)*BA12) -> -1360.8 | BE12: =IF(LEFT(M12,4)="call","Call",IF(LEFT(M12,3)="put","Put","Futuro")) -> Call | BF12: =IF(BE12="futuro","no","si") -> si | BG12: =IF(AL12=0,"V","C") -> V | BH12: =IF(BE12="futuro","",CONCATENATE(BG12,LEFT(BE12,1))) -> VC | BI12: =$BB12*(1+BI$2) -> 287.22922 | BJ12: =$BB12*(1+BJ$2) -> 328.26196 | BK12: =$BB12*(1+BK$2) -> 369.29471 | BL12: =$BB12*(1+BL$2) -> 410.32745 | BM12: =$BB12*(1+BM$2) -> 451.3602 | BN12: =$BB12*(1+BN$2) -> 492.39294 | BO12: =$BB12*(1+BO$2) -> 533.42569 | BP12: =IF($BE12="futuro",-($BL12-BI12)*$BD12,0) -> 0 | BQ12: =IF($BE12="futuro",-($BL12-BJ12)*$BD12,0) -> 0 | BR12: =IF($BE12="futuro",-($BL12-BK12)*$BD12,0) -> 0 | BS12: =IF($BE12="futuro",-($BL12-BL12)*$BD12,0) -> 0 | BT12: =IF($BE12="futuro",-($BL12-BM12)*$BD12,0) -> 0 | BU12: =IF($BE12="futuro",-($BL12-BN12)*$BD12,0) -> 0 | BV12: =IF($BE12="futuro",-($BL12-BO12)*$BD12,0) -> 0 | BW12: =IF(AND($BH12="CC",($BC12-BI12)<0),(BI12-$BC12)*$BD12, IF(AND($BH12="VC",($BC12-BI12)<0),($BC12-BI12)*-$BD12, IF(AND($BH12="CP",($BC12-BI12)>0),(BI12-$BC12)*$BD12*-1, IF(AND($BH12="VP",($BC12-BI12)>0),(BI12-$BC12)*$BD12*-1,0)))) -> 0 | BX12: =IF(AND($BH12="CC",($BC12-BJ12)<0),(BJ12-$BC12)*$BD12, IF(AND($BH12="VC",($BC12-BJ12)<0),($BC12-BJ12)*-$BD12, IF(AND($BH12="CP",($BC12-BJ12)>0),(BJ12-$BC12)*$BD12*-1, IF(AND($BH12="VP",($BC12-BJ12)>0),(BJ12-$BC12)*$BD12*-1,0)))) -> 0 | BY12: =IF(AND($BH12="CC",($BC12-BK12)<0),(BK12-$BC12)*$BD12, IF(AND($BH12="VC",($BC12-BK12)<0),($BC12-BK12)*-$BD12, IF(AND($BH12="CP",($BC12-BK12)>0),(BK12-$BC12)*$BD12*-1, IF(AND($BH12="VP",($BC12-BK12)>0),(BK12-$BC12)*$BD12*-1,0)))) -> 0 | BZ12: =IF(AND($BH12="CC",($BC12-BL12)<0),(BL12-$BC12)*$BD12, IF(AND($BH12="VC",($BC12-BL12)<0),($BC12-BL12)*-$BD12, IF(AND($BH12="CP",($BC12-BL12)>0),(BL12-$BC12)*$BD12*-1, IF(AND($BH12="VP",($BC12-BL12)>0),(BL12-$BC12)*$BD12*-1,0)))) -> 0 | CA12: =IF(AND($BH12="CC",($BC12-BM12)<0),(BM12-$BC12)*$BD12, IF(AND($BH12="VC",($BC12-BM12)<0),($BC12-BM12)*-$BD12, IF(AND($BH12="CP",($BC12-BM12)>0),(BM12-$BC12)*$BD12*-1, IF(AND($BH12="VP",($BC12-BM12)>0),(BM12-$BC12)*$BD12*-1,0)))) -> -24212.439 | CB12: =IF(AND($BH12="CC",($BC12-BN12)<0),(BN12-$BC12)*$BD12, IF(AND($BH12="VC",($BC12-BN12)<0),($BC12-BN12)*-$BD12, IF(AND($BH12="CP",($BC12-BN12)>0),(BN12-$BC12)*$BD12*-1, IF(AND($BH12="VP",($BC12-BN12)>0),(BN12-$BC12)*$BD12*-1,0)))) -> -80049.799 | CC12: =IF(AND($BH12="CC",($BC12-BO12)<0),(BO12-$BC12)*$BD12, IF(AND($BH12="VC",($BC12-BO12)<0),($BC12-BO12)*-$BD12, IF(AND($BH12="CP",($BC12-BO12)>0),(BO12-$BC12)*$BD12*-1, IF(AND($BH12="VP",($BC12-BO12)>0),(BO12-$BC12)*$BD12*-1,0)))) -> -135887.16 | CD12: =IF(AND($BH12="CC",($BC12-BI12)<0),$BD12*1, IF(AND($BH12="VC",($BC12-BI12)<0),$BD12*1, IF(AND($BH12="CP",($BC12-BI12)>0),$BD12*-1, IF(AND($BH12="VP",($BC12-BI12)>0),$BD12*-1,0)))) -> 0 | CE12: =IF(AND($BH12="CC",($BC12-BJ12)<0),$BD12*1, IF(AND($BH12="VC",($BC12-BJ12)<0),$BD12*1, IF(AND($BH12="CP",($BC12-BJ12)>0),$BD12*-1, IF(AND($BH12="VP",($BC12-BJ12)>0),$BD12*-1,0)))) -> 0 | CF12: =IF(AND($BH12="CC",($BC12-BK12)<0),$BD12*1, IF(AND($BH12="VC",($BC12-BK12)<0),$BD12*1, IF(AND($BH12="CP",($BC12-BK12)>0),$BD12*-1, IF(AND($BH12="VP",($BC12-BK12)>0),$BD12*-1,0)))) -> 0 | CG12: =IF(AND($BH12="CC",($BC12-BL12)<0),$BD12*1, IF(AND($BH12="VC",($BC12-BL12)<0),$BD12*1, IF(AND($BH12="CP",($BC12-BL12)>0),$BD12*-1, IF(AND($BH12="VP",($BC12-BL12)>0),$BD12*-1,0)))) -> 0 | CH12: =IF(AND($BH12="CC",($BC12-BM12)<0),$BD12*1, IF(AND($BH12="VC",($BC12-BM12)<0),$BD12*1, IF(AND($BH12="CP",($BC12-BM12)>0),$BD12*-1, IF(AND($BH12="VP",($BC12-BM12)>0),$BD12*-1,0)))) -> -1360.8 | CI12: =IF(AND($BH12="CC",($BC12-BN12)<0),$BD12*1, IF(AND($BH12="VC",($BC12-BN12)<0),$BD12*1, IF(AND($BH12="CP",($BC12-BN12)>0),$BD12*-1, IF(AND($BH12="VP",($BC12-BN12)>0),$BD12*-1,0)))) -> -1360.8 | CJ12: =IF(AND($BH12="CC",($BC12-BO12)<0),$BD12*1, IF(AND($BH12="VC",($BC12-BO12)<0),$BD12*1, IF(AND($BH12="CP",($BC12-BO12)>0),$BD12*-1, IF(AND($BH12="VP",($BC12-BO12)>0),$BD12*-1,0)))) -> -1360.8 | CK12: =Tabla3[[#This Row],[Tns]] -> -1360.8 | CL12: =IF(ISERROR(VLOOKUP(VALUE(E12),'Clientes CBOT'!A:A,1,0)),"VER","ok") -> ok
